telegram.ext.dispatcher - ERROR - An uncaught error was raised while processing the update
Traceback (most recent call last):
  File "C:\Python34\lib\site-packages\telegram\ext\dispatcher.py", line 279, in process_update
    handler.handle_update(update, self)
  File "C:\Python34\lib\site-packages\telegram\ext\commandhandler.py", line 171, in handle_update
    return self.callback(dispatcher.bot, update, **optional_args)
  File "bot.py", line 12, in greet_user
    update.message.reply_text(update)
  File "C:\Python34\lib\site-packages\telegram\message.py", line 427, in reply_text
    return self.bot.send_message(self.chat_id, *args, **kwargs)
  File "C:\Python34\lib\site-packages\telegram\bot.py", line 60, in decorator
    result = func(self, *args, **kwargs)
  File "C:\Python34\lib\site-packages\telegram\bot.py", line 85, in decorator
    result = self._request.post(url, data, timeout=kwargs.get('timeout'))
  File "C:\Python34\lib\site-packages\telegram\utils\request.py", line 266, in post
    data = json.dumps(data)
  File "C:\Python34\lib\json\__init__.py", line 230, in dumps
    return _default_encoder.encode(obj)
  File "C:\Python34\lib\json\encoder.py", line 192, in encode
    chunks = self.iterencode(o, _one_shot=True)
  File "C:\Python34\lib\json\encoder.py", line 250, in iterencode
    return _iterencode(o, 0)
  File "C:\Python34\lib\json\encoder.py", line 173, in default
    raise TypeError(repr(o) + " is not JSON serializable")
TypeError: <telegram.update.Update object at 0x00000000033AEC88> is not JSON serializable
telegram.ext.updater - WARNING - Exiting immediately!
telegram.ext.dispatcher - ERROR - An uncaught error was raised while processing the update
Traceback (most recent call last):
  File "C:\Python34\lib\site-packages\telegram\ext\dispatcher.py", line 279, in process_update
    handler.handle_update(update, self)
  File "C:\Python34\lib\site-packages\telegram\ext\commandhandler.py", line 171, in handle_update
    return self.callback(dispatcher.bot, update, **optional_args)
  File "bot.py", line 17, in update
    update.message.reply_text(update)
  File "C:\Python34\lib\site-packages\telegram\message.py", line 427, in reply_text
    return self.bot.send_message(self.chat_id, *args, **kwargs)
  File "C:\Python34\lib\site-packages\telegram\bot.py", line 60, in decorator
    result = func(self, *args, **kwargs)
  File "C:\Python34\lib\site-packages\telegram\bot.py", line 85, in decorator
    result = self._request.post(url, data, timeout=kwargs.get('timeout'))
  File "C:\Python34\lib\site-packages\telegram\utils\request.py", line 266, in post
    data = json.dumps(data)
  File "C:\Python34\lib\json\__init__.py", line 230, in dumps
    return _default_encoder.encode(obj)
  File "C:\Python34\lib\json\encoder.py", line 192, in encode
    chunks = self.iterencode(o, _one_shot=True)
  File "C:\Python34\lib\json\encoder.py", line 250, in iterencode
    return _iterencode(o, 0)
  File "C:\Python34\lib\json\encoder.py", line 173, in default
    raise TypeError(repr(o) + " is not JSON serializable")
TypeError: <telegram.update.Update object at 0x0000000003441518> is not JSON serializable
telegram.ext.updater - WARNING - Exiting immediately!
telegram.ext.updater - WARNING - Exiting immediately!
telegram.ext.dispatcher - ERROR - An uncaught error was raised while processing the update
Traceback (most recent call last):
  File "C:\Python34\lib\site-packages\telegram\ext\dispatcher.py", line 279, in process_update
    handler.handle_update(update, self)
  File "C:\Python34\lib\site-packages\telegram\ext\commandhandler.py", line 171, in handle_update
    return self.callback(dispatcher.bot, update, **optional_args)
  File "bot.py", line 17, in update
    update.message.reply_text(update)
  File "C:\Python34\lib\site-packages\telegram\message.py", line 427, in reply_text
    return self.bot.send_message(self.chat_id, *args, **kwargs)
  File "C:\Python34\lib\site-packages\telegram\bot.py", line 60, in decorator
    result = func(self, *args, **kwargs)
  File "C:\Python34\lib\site-packages\telegram\bot.py", line 85, in decorator
    result = self._request.post(url, data, timeout=kwargs.get('timeout'))
  File "C:\Python34\lib\site-packages\telegram\utils\request.py", line 266, in post
    data = json.dumps(data)
  File "C:\Python34\lib\json\__init__.py", line 230, in dumps
    return _default_encoder.encode(obj)
  File "C:\Python34\lib\json\encoder.py", line 192, in encode
    chunks = self.iterencode(o, _one_shot=True)
  File "C:\Python34\lib\json\encoder.py", line 250, in iterencode
    return _iterencode(o, 0)
  File "C:\Python34\lib\json\encoder.py", line 173, in default
    raise TypeError(repr(o) + " is not JSON serializable")
TypeError: <telegram.update.Update object at 0x0000000003E9E518> is not JSON serializable
telegram.ext.updater - WARNING - Exiting immediately!
telegram.ext.dispatcher - ERROR - An uncaught error was raised while processing the update
Traceback (most recent call last):
  File "C:\Python34\lib\site-packages\telegram\ext\dispatcher.py", line 279, in process_update
    handler.handle_update(update, self)
  File "C:\Python34\lib\site-packages\telegram\ext\commandhandler.py", line 171, in handle_update
    return self.callback(dispatcher.bot, update, **optional_args)
  File "bot.py", line 16, in update
    update.message.reply_text(update)
  File "C:\Python34\lib\site-packages\telegram\message.py", line 427, in reply_text
    return self.bot.send_message(self.chat_id, *args, **kwargs)
  File "C:\Python34\lib\site-packages\telegram\bot.py", line 60, in decorator
    result = func(self, *args, **kwargs)
  File "C:\Python34\lib\site-packages\telegram\bot.py", line 85, in decorator
    result = self._request.post(url, data, timeout=kwargs.get('timeout'))
  File "C:\Python34\lib\site-packages\telegram\utils\request.py", line 266, in post
    data = json.dumps(data)
  File "C:\Python34\lib\json\__init__.py", line 230, in dumps
    return _default_encoder.encode(obj)
  File "C:\Python34\lib\json\encoder.py", line 192, in encode
    chunks = self.iterencode(o, _one_shot=True)
  File "C:\Python34\lib\json\encoder.py", line 250, in iterencode
    return _iterencode(o, 0)
  File "C:\Python34\lib\json\encoder.py", line 173, in default
    raise TypeError(repr(o) + " is not JSON serializable")
TypeError: <telegram.update.Update object at 0x0000000003AEE550> is not JSON serializable
telegram.ext.updater - WARNING - Exiting immediately!
telegram.ext.dispatcher - ERROR - An uncaught error was raised while processing the update
Traceback (most recent call last):
  File "C:\Python34\lib\site-packages\telegram\ext\dispatcher.py", line 279, in process_update
    handler.handle_update(update, self)
  File "C:\Python34\lib\site-packages\telegram\ext\commandhandler.py", line 171, in handle_update
    return self.callback(dispatcher.bot, update, **optional_args)
  File "bot.py", line 16, in update
    update.message.reply_text(update)
  File "C:\Python34\lib\site-packages\telegram\message.py", line 427, in reply_text
    return self.bot.send_message(self.chat_id, *args, **kwargs)
  File "C:\Python34\lib\site-packages\telegram\bot.py", line 60, in decorator
    result = func(self, *args, **kwargs)
  File "C:\Python34\lib\site-packages\telegram\bot.py", line 85, in decorator
    result = self._request.post(url, data, timeout=kwargs.get('timeout'))
  File "C:\Python34\lib\site-packages\telegram\utils\request.py", line 266, in post
    data = json.dumps(data)
  File "C:\Python34\lib\json\__init__.py", line 230, in dumps
    return _default_encoder.encode(obj)
  File "C:\Python34\lib\json\encoder.py", line 192, in encode
    chunks = self.iterencode(o, _one_shot=True)
  File "C:\Python34\lib\json\encoder.py", line 250, in iterencode
    return _iterencode(o, 0)
  File "C:\Python34\lib\json\encoder.py", line 173, in default
    raise TypeError(repr(o) + " is not JSON serializable")
TypeError: <telegram.update.Update object at 0x000000000373E550> is not JSON serializable
telegram.ext.dispatcher - ERROR - An uncaught error was raised while processing the update
Traceback (most recent call last):
  File "C:\Python34\lib\site-packages\telegram\ext\dispatcher.py", line 279, in process_update
    handler.handle_update(update, self)
  File "C:\Python34\lib\site-packages\telegram\ext\commandhandler.py", line 171, in handle_update
    return self.callback(dispatcher.bot, update, **optional_args)
  File "bot.py", line 16, in update
    update.message.reply_text(update)
  File "C:\Python34\lib\site-packages\telegram\message.py", line 427, in reply_text
    return self.bot.send_message(self.chat_id, *args, **kwargs)
  File "C:\Python34\lib\site-packages\telegram\bot.py", line 60, in decorator
    result = func(self, *args, **kwargs)
  File "C:\Python34\lib\site-packages\telegram\bot.py", line 85, in decorator
    result = self._request.post(url, data, timeout=kwargs.get('timeout'))
  File "C:\Python34\lib\site-packages\telegram\utils\request.py", line 266, in post
    data = json.dumps(data)
  File "C:\Python34\lib\json\__init__.py", line 230, in dumps
    return _default_encoder.encode(obj)
  File "C:\Python34\lib\json\encoder.py", line 192, in encode
    chunks = self.iterencode(o, _one_shot=True)
  File "C:\Python34\lib\json\encoder.py", line 250, in iterencode
    return _iterencode(o, 0)
  File "C:\Python34\lib\json\encoder.py", line 173, in default
    raise TypeError(repr(o) + " is not JSON serializable")
TypeError: <telegram.update.Update object at 0x0000000004F4E0F0> is not JSON serializable
telegram.ext.dispatcher - ERROR - An uncaught error was raised while processing the update
Traceback (most recent call last):
  File "C:\Python34\lib\site-packages\telegram\ext\dispatcher.py", line 279, in process_update
    handler.handle_update(update, self)
  File "C:\Python34\lib\site-packages\telegram\ext\commandhandler.py", line 171, in handle_update
    return self.callback(dispatcher.bot, update, **optional_args)
  File "bot.py", line 16, in update
    update.message.reply_text(update)
  File "C:\Python34\lib\site-packages\telegram\message.py", line 427, in reply_text
    return self.bot.send_message(self.chat_id, *args, **kwargs)
  File "C:\Python34\lib\site-packages\telegram\bot.py", line 60, in decorator
    result = func(self, *args, **kwargs)
  File "C:\Python34\lib\site-packages\telegram\bot.py", line 85, in decorator
    result = self._request.post(url, data, timeout=kwargs.get('timeout'))
  File "C:\Python34\lib\site-packages\telegram\utils\request.py", line 266, in post
    data = json.dumps(data)
  File "C:\Python34\lib\json\__init__.py", line 230, in dumps
    return _default_encoder.encode(obj)
  File "C:\Python34\lib\json\encoder.py", line 192, in encode
    chunks = self.iterencode(o, _one_shot=True)
  File "C:\Python34\lib\json\encoder.py", line 250, in iterencode
    return _iterencode(o, 0)
  File "C:\Python34\lib\json\encoder.py", line 173, in default
    raise TypeError(repr(o) + " is not JSON serializable")
TypeError: <telegram.update.Update object at 0x0000000004F4E2B0> is not JSON serializable
telegram.ext.dispatcher - ERROR - An uncaught error was raised while processing the update
Traceback (most recent call last):
  File "C:\Python34\lib\site-packages\telegram\ext\dispatcher.py", line 279, in process_update
    handler.handle_update(update, self)
  File "C:\Python34\lib\site-packages\telegram\ext\commandhandler.py", line 171, in handle_update
    return self.callback(dispatcher.bot, update, **optional_args)
  File "bot.py", line 16, in update
    update.message.reply_text(update)
  File "C:\Python34\lib\site-packages\telegram\message.py", line 427, in reply_text
    return self.bot.send_message(self.chat_id, *args, **kwargs)
  File "C:\Python34\lib\site-packages\telegram\bot.py", line 60, in decorator
    result = func(self, *args, **kwargs)
  File "C:\Python34\lib\site-packages\telegram\bot.py", line 85, in decorator
    result = self._request.post(url, data, timeout=kwargs.get('timeout'))
  File "C:\Python34\lib\site-packages\telegram\utils\request.py", line 266, in post
    data = json.dumps(data)
  File "C:\Python34\lib\json\__init__.py", line 230, in dumps
    return _default_encoder.encode(obj)
  File "C:\Python34\lib\json\encoder.py", line 192, in encode
    chunks = self.iterencode(o, _one_shot=True)
  File "C:\Python34\lib\json\encoder.py", line 250, in iterencode
    return _iterencode(o, 0)
  File "C:\Python34\lib\json\encoder.py", line 173, in default
    raise TypeError(repr(o) + " is not JSON serializable")
TypeError: <telegram.update.Update object at 0x0000000004F4E438> is not JSON serializable
telegram.ext.updater - WARNING - Exiting immediately!
telegram.ext.updater - WARNING - Exiting immediately!
telegram.ext.updater - WARNING - Exiting immediately!
telegram.vendor.ptb_urllib3.urllib3.connectionpool - WARNING - Retrying (Retry(total=2, connect=None, read=None, redirect=None)) after connection broken by 'NewConnectionError('<telegram.vendor.ptb_urllib3.urllib3.connection.VerifiedHTTPSConnection object at 0x7f0b90eb2c88>: Failed to establish a new connection: [Errno -3] Temporary failure in name resolution',)': /bot504744759:AAFLDudnlMRy7yyp196gpyAqQtbdntWEwkw/setWebhook
telegram.vendor.ptb_urllib3.urllib3.connectionpool - WARNING - Retrying (Retry(total=1, connect=None, read=None, redirect=None)) after connection broken by 'NewConnectionError('<telegram.vendor.ptb_urllib3.urllib3.connection.VerifiedHTTPSConnection object at 0x7f0b90eb2cf8>: Failed to establish a new connection: [Errno -3] Temporary failure in name resolution',)': /bot504744759:AAFLDudnlMRy7yyp196gpyAqQtbdntWEwkw/setWebhook
telegram.vendor.ptb_urllib3.urllib3.connectionpool - WARNING - Retrying (Retry(total=0, connect=None, read=None, redirect=None)) after connection broken by 'NewConnectionError('<telegram.vendor.ptb_urllib3.urllib3.connection.VerifiedHTTPSConnection object at 0x7f0b90eb2d68>: Failed to establish a new connection: [Errno -3] Temporary failure in name resolution',)': /bot504744759:AAFLDudnlMRy7yyp196gpyAqQtbdntWEwkw/setWebhook
telegram.ext.updater - ERROR - error in bootstrap phase; try=0 max_retries=0
Traceback (most recent call last):
  File "/home/p/.local/lib/python3.5/site-packages/telegram/vendor/ptb_urllib3/urllib3/connection.py", line 141, in _new_conn
    (self.host, self.port), self.timeout, **extra_kw)
  File "/home/p/.local/lib/python3.5/site-packages/telegram/vendor/ptb_urllib3/urllib3/util/connection.py", line 60, in create_connection
    for res in socket.getaddrinfo(host, port, family, socket.SOCK_STREAM):
  File "/usr/lib/python3.5/socket.py", line 732, in getaddrinfo
    for res in _socket.getaddrinfo(host, port, family, type, proto, flags):
socket.gaierror: [Errno -3] Temporary failure in name resolution

During handling of the above exception, another exception occurred:

Traceback (most recent call last):
  File "/home/p/.local/lib/python3.5/site-packages/telegram/vendor/ptb_urllib3/urllib3/connectionpool.py", line 617, in urlopen
    chunked=chunked)
  File "/home/p/.local/lib/python3.5/site-packages/telegram/vendor/ptb_urllib3/urllib3/connectionpool.py", line 360, in _make_request
    self._validate_conn(conn)
  File "/home/p/.local/lib/python3.5/site-packages/telegram/vendor/ptb_urllib3/urllib3/connectionpool.py", line 857, in _validate_conn
    super(HTTPSConnectionPool, self)._validate_conn(conn)
  File "/home/p/.local/lib/python3.5/site-packages/telegram/vendor/ptb_urllib3/urllib3/connectionpool.py", line 289, in _validate_conn
    conn.connect()
  File "/home/p/.local/lib/python3.5/site-packages/telegram/vendor/ptb_urllib3/urllib3/connection.py", line 284, in connect
    conn = self._new_conn()
  File "/home/p/.local/lib/python3.5/site-packages/telegram/vendor/ptb_urllib3/urllib3/connection.py", line 150, in _new_conn
    self, "Failed to establish a new connection: %s" % e)
telegram.vendor.ptb_urllib3.urllib3.exceptions.NewConnectionError: <telegram.vendor.ptb_urllib3.urllib3.connection.VerifiedHTTPSConnection object at 0x7f0b9064b860>: Failed to establish a new connection: [Errno -3] Temporary failure in name resolution

During handling of the above exception, another exception occurred:

Traceback (most recent call last):
  File "/home/p/.local/lib/python3.5/site-packages/telegram/utils/request.py", line 190, in _request_wrapper
    resp = self._con_pool.request(*args, **kwargs)
  File "/home/p/.local/lib/python3.5/site-packages/telegram/vendor/ptb_urllib3/urllib3/request.py", line 70, in request
    **urlopen_kw)
  File "/home/p/.local/lib/python3.5/site-packages/telegram/vendor/ptb_urllib3/urllib3/request.py", line 148, in request_encode_body
    return self.urlopen(method, url, **extra_kw)
  File "/home/p/.local/lib/python3.5/site-packages/telegram/vendor/ptb_urllib3/urllib3/poolmanager.py", line 244, in urlopen
    response = conn.urlopen(method, u.request_uri, **kw)
  File "/home/p/.local/lib/python3.5/site-packages/telegram/vendor/ptb_urllib3/urllib3/connectionpool.py", line 695, in urlopen
    **response_kw)
  File "/home/p/.local/lib/python3.5/site-packages/telegram/vendor/ptb_urllib3/urllib3/connectionpool.py", line 695, in urlopen
    **response_kw)
  File "/home/p/.local/lib/python3.5/site-packages/telegram/vendor/ptb_urllib3/urllib3/connectionpool.py", line 695, in urlopen
    **response_kw)
  File "/home/p/.local/lib/python3.5/site-packages/telegram/vendor/ptb_urllib3/urllib3/connectionpool.py", line 666, in urlopen
    _stacktrace=sys.exc_info()[2])
  File "/home/p/.local/lib/python3.5/site-packages/telegram/vendor/ptb_urllib3/urllib3/util/retry.py", line 376, in increment
    raise MaxRetryError(_pool, url, error or ResponseError(cause))
telegram.vendor.ptb_urllib3.urllib3.exceptions.MaxRetryError: HTTPSConnectionPool(host='api.telegram.org', port=443): Max retries exceeded with url: /bot504744759:AAFLDudnlMRy7yyp196gpyAqQtbdntWEwkw/setWebhook (Caused by NewConnectionError('<telegram.vendor.ptb_urllib3.urllib3.connection.VerifiedHTTPSConnection object at 0x7f0b9064b860>: Failed to establish a new connection: [Errno -3] Temporary failure in name resolution',))

During handling of the above exception, another exception occurred:

Traceback (most recent call last):
  File "/home/p/.local/lib/python3.5/site-packages/telegram/ext/updater.py", line 390, in _bootstrap
    url=webhook_url, certificate=cert, allowed_updates=allowed_updates)
  File "/home/p/.local/lib/python3.5/site-packages/telegram/bot.py", line 60, in decorator
    result = func(self, *args, **kwargs)
  File "/home/p/.local/lib/python3.5/site-packages/telegram/bot.py", line 1813, in set_webhook
    result = self._request.post(url_, data, timeout=timeout)
  File "/home/p/.local/lib/python3.5/site-packages/telegram/utils/request.py", line 272, in post
    **urlopen_kwargs)
  File "/home/p/.local/lib/python3.5/site-packages/telegram/utils/request.py", line 196, in _request_wrapper
    raise NetworkError('urllib3 HTTPError {0}'.format(error))
telegram.error.NetworkError: urllib3 HTTPError HTTPSConnectionPool(host='api.telegram.org', port=443): Max retries exceeded with url: /bot504744759:AAFLDudnlMRy7yyp196gpyAqQtbdntWEwkw/setWebhook (Caused by NewConnectionError('<telegram.vendor.ptb_urllib3.urllib3.connection.VerifiedHTTPSConnection object at 0x7f0b9064b860>: Failed to establish a new connection: [Errno -3] Temporary failure in name resolution',))
telegram.ext.updater - ERROR - unhandled exception
Traceback (most recent call last):
  File "/home/p/.local/lib/python3.5/site-packages/telegram/vendor/ptb_urllib3/urllib3/connection.py", line 141, in _new_conn
    (self.host, self.port), self.timeout, **extra_kw)
  File "/home/p/.local/lib/python3.5/site-packages/telegram/vendor/ptb_urllib3/urllib3/util/connection.py", line 60, in create_connection
    for res in socket.getaddrinfo(host, port, family, socket.SOCK_STREAM):
  File "/usr/lib/python3.5/socket.py", line 732, in getaddrinfo
    for res in _socket.getaddrinfo(host, port, family, type, proto, flags):
socket.gaierror: [Errno -3] Temporary failure in name resolution

During handling of the above exception, another exception occurred:

Traceback (most recent call last):
  File "/home/p/.local/lib/python3.5/site-packages/telegram/vendor/ptb_urllib3/urllib3/connectionpool.py", line 617, in urlopen
    chunked=chunked)
  File "/home/p/.local/lib/python3.5/site-packages/telegram/vendor/ptb_urllib3/urllib3/connectionpool.py", line 360, in _make_request
    self._validate_conn(conn)
  File "/home/p/.local/lib/python3.5/site-packages/telegram/vendor/ptb_urllib3/urllib3/connectionpool.py", line 857, in _validate_conn
    super(HTTPSConnectionPool, self)._validate_conn(conn)
  File "/home/p/.local/lib/python3.5/site-packages/telegram/vendor/ptb_urllib3/urllib3/connectionpool.py", line 289, in _validate_conn
    conn.connect()
  File "/home/p/.local/lib/python3.5/site-packages/telegram/vendor/ptb_urllib3/urllib3/connection.py", line 284, in connect
    conn = self._new_conn()
  File "/home/p/.local/lib/python3.5/site-packages/telegram/vendor/ptb_urllib3/urllib3/connection.py", line 150, in _new_conn
    self, "Failed to establish a new connection: %s" % e)
telegram.vendor.ptb_urllib3.urllib3.exceptions.NewConnectionError: <telegram.vendor.ptb_urllib3.urllib3.connection.VerifiedHTTPSConnection object at 0x7f0b9064b860>: Failed to establish a new connection: [Errno -3] Temporary failure in name resolution

During handling of the above exception, another exception occurred:

Traceback (most recent call last):
  File "/home/p/.local/lib/python3.5/site-packages/telegram/utils/request.py", line 190, in _request_wrapper
    resp = self._con_pool.request(*args, **kwargs)
  File "/home/p/.local/lib/python3.5/site-packages/telegram/vendor/ptb_urllib3/urllib3/request.py", line 70, in request
    **urlopen_kw)
  File "/home/p/.local/lib/python3.5/site-packages/telegram/vendor/ptb_urllib3/urllib3/request.py", line 148, in request_encode_body
    return self.urlopen(method, url, **extra_kw)
  File "/home/p/.local/lib/python3.5/site-packages/telegram/vendor/ptb_urllib3/urllib3/poolmanager.py", line 244, in urlopen
    response = conn.urlopen(method, u.request_uri, **kw)
  File "/home/p/.local/lib/python3.5/site-packages/telegram/vendor/ptb_urllib3/urllib3/connectionpool.py", line 695, in urlopen
    **response_kw)
  File "/home/p/.local/lib/python3.5/site-packages/telegram/vendor/ptb_urllib3/urllib3/connectionpool.py", line 695, in urlopen
    **response_kw)
  File "/home/p/.local/lib/python3.5/site-packages/telegram/vendor/ptb_urllib3/urllib3/connectionpool.py", line 695, in urlopen
    **response_kw)
  File "/home/p/.local/lib/python3.5/site-packages/telegram/vendor/ptb_urllib3/urllib3/connectionpool.py", line 666, in urlopen
    _stacktrace=sys.exc_info()[2])
  File "/home/p/.local/lib/python3.5/site-packages/telegram/vendor/ptb_urllib3/urllib3/util/retry.py", line 376, in increment
    raise MaxRetryError(_pool, url, error or ResponseError(cause))
telegram.vendor.ptb_urllib3.urllib3.exceptions.MaxRetryError: HTTPSConnectionPool(host='api.telegram.org', port=443): Max retries exceeded with url: /bot504744759:AAFLDudnlMRy7yyp196gpyAqQtbdntWEwkw/setWebhook (Caused by NewConnectionError('<telegram.vendor.ptb_urllib3.urllib3.connection.VerifiedHTTPSConnection object at 0x7f0b9064b860>: Failed to establish a new connection: [Errno -3] Temporary failure in name resolution',))

During handling of the above exception, another exception occurred:

Traceback (most recent call last):
  File "/home/p/.local/lib/python3.5/site-packages/telegram/ext/updater.py", line 149, in _thread_wrapper
    target(*args, **kwargs)
  File "/home/p/.local/lib/python3.5/site-packages/telegram/ext/updater.py", line 278, in _start_polling
    self._bootstrap(bootstrap_retries, clean=clean, webhook_url='', allowed_updates=None)
  File "/home/p/.local/lib/python3.5/site-packages/telegram/ext/updater.py", line 390, in _bootstrap
    url=webhook_url, certificate=cert, allowed_updates=allowed_updates)
  File "/home/p/.local/lib/python3.5/site-packages/telegram/bot.py", line 60, in decorator
    result = func(self, *args, **kwargs)
  File "/home/p/.local/lib/python3.5/site-packages/telegram/bot.py", line 1813, in set_webhook
    result = self._request.post(url_, data, timeout=timeout)
  File "/home/p/.local/lib/python3.5/site-packages/telegram/utils/request.py", line 272, in post
    **urlopen_kwargs)
  File "/home/p/.local/lib/python3.5/site-packages/telegram/utils/request.py", line 196, in _request_wrapper
    raise NetworkError('urllib3 HTTPError {0}'.format(error))
telegram.error.NetworkError: urllib3 HTTPError HTTPSConnectionPool(host='api.telegram.org', port=443): Max retries exceeded with url: /bot504744759:AAFLDudnlMRy7yyp196gpyAqQtbdntWEwkw/setWebhook (Caused by NewConnectionError('<telegram.vendor.ptb_urllib3.urllib3.connection.VerifiedHTTPSConnection object at 0x7f0b9064b860>: Failed to establish a new connection: [Errno -3] Temporary failure in name resolution',))
telegram.ext.dispatcher - CRITICAL - stopping due to exception in another thread
telegram.vendor.ptb_urllib3.urllib3.connectionpool - WARNING - Retrying (Retry(total=2, connect=None, read=None, redirect=None)) after connection broken by 'NewConnectionError('<telegram.vendor.ptb_urllib3.urllib3.connection.VerifiedHTTPSConnection object at 0x7fb0f23857f0>: Failed to establish a new connection: [Errno -3] Temporary failure in name resolution',)': /bot504744759:AAFLDudnlMRy7yyp196gpyAqQtbdntWEwkw/setWebhook
telegram.vendor.ptb_urllib3.urllib3.connectionpool - WARNING - Retrying (Retry(total=1, connect=None, read=None, redirect=None)) after connection broken by 'NewConnectionError('<telegram.vendor.ptb_urllib3.urllib3.connection.VerifiedHTTPSConnection object at 0x7fb0f2385908>: Failed to establish a new connection: [Errno -3] Temporary failure in name resolution',)': /bot504744759:AAFLDudnlMRy7yyp196gpyAqQtbdntWEwkw/setWebhook
telegram.vendor.ptb_urllib3.urllib3.connectionpool - WARNING - Retrying (Retry(total=0, connect=None, read=None, redirect=None)) after connection broken by 'NewConnectionError('<telegram.vendor.ptb_urllib3.urllib3.connection.VerifiedHTTPSConnection object at 0x7fb0f2385dd8>: Failed to establish a new connection: [Errno -3] Temporary failure in name resolution',)': /bot504744759:AAFLDudnlMRy7yyp196gpyAqQtbdntWEwkw/setWebhook
telegram.ext.updater - ERROR - error in bootstrap phase; try=0 max_retries=0
Traceback (most recent call last):
  File "/home/p/.local/lib/python3.5/site-packages/telegram/vendor/ptb_urllib3/urllib3/connection.py", line 141, in _new_conn
    (self.host, self.port), self.timeout, **extra_kw)
  File "/home/p/.local/lib/python3.5/site-packages/telegram/vendor/ptb_urllib3/urllib3/util/connection.py", line 60, in create_connection
    for res in socket.getaddrinfo(host, port, family, socket.SOCK_STREAM):
  File "/usr/lib/python3.5/socket.py", line 732, in getaddrinfo
    for res in _socket.getaddrinfo(host, port, family, type, proto, flags):
socket.gaierror: [Errno -3] Temporary failure in name resolution

During handling of the above exception, another exception occurred:

Traceback (most recent call last):
  File "/home/p/.local/lib/python3.5/site-packages/telegram/vendor/ptb_urllib3/urllib3/connectionpool.py", line 617, in urlopen
    chunked=chunked)
  File "/home/p/.local/lib/python3.5/site-packages/telegram/vendor/ptb_urllib3/urllib3/connectionpool.py", line 360, in _make_request
    self._validate_conn(conn)
  File "/home/p/.local/lib/python3.5/site-packages/telegram/vendor/ptb_urllib3/urllib3/connectionpool.py", line 857, in _validate_conn
    super(HTTPSConnectionPool, self)._validate_conn(conn)
  File "/home/p/.local/lib/python3.5/site-packages/telegram/vendor/ptb_urllib3/urllib3/connectionpool.py", line 289, in _validate_conn
    conn.connect()
  File "/home/p/.local/lib/python3.5/site-packages/telegram/vendor/ptb_urllib3/urllib3/connection.py", line 284, in connect
    conn = self._new_conn()
  File "/home/p/.local/lib/python3.5/site-packages/telegram/vendor/ptb_urllib3/urllib3/connection.py", line 150, in _new_conn
    self, "Failed to establish a new connection: %s" % e)
telegram.vendor.ptb_urllib3.urllib3.exceptions.NewConnectionError: <telegram.vendor.ptb_urllib3.urllib3.connection.VerifiedHTTPSConnection object at 0x7fb0f03183c8>: Failed to establish a new connection: [Errno -3] Temporary failure in name resolution

During handling of the above exception, another exception occurred:

Traceback (most recent call last):
  File "/home/p/.local/lib/python3.5/site-packages/telegram/utils/request.py", line 190, in _request_wrapper
    resp = self._con_pool.request(*args, **kwargs)
  File "/home/p/.local/lib/python3.5/site-packages/telegram/vendor/ptb_urllib3/urllib3/request.py", line 70, in request
    **urlopen_kw)
  File "/home/p/.local/lib/python3.5/site-packages/telegram/vendor/ptb_urllib3/urllib3/request.py", line 148, in request_encode_body
    return self.urlopen(method, url, **extra_kw)
  File "/home/p/.local/lib/python3.5/site-packages/telegram/vendor/ptb_urllib3/urllib3/poolmanager.py", line 244, in urlopen
    response = conn.urlopen(method, u.request_uri, **kw)
  File "/home/p/.local/lib/python3.5/site-packages/telegram/vendor/ptb_urllib3/urllib3/connectionpool.py", line 695, in urlopen
    **response_kw)
  File "/home/p/.local/lib/python3.5/site-packages/telegram/vendor/ptb_urllib3/urllib3/connectionpool.py", line 695, in urlopen
    **response_kw)
  File "/home/p/.local/lib/python3.5/site-packages/telegram/vendor/ptb_urllib3/urllib3/connectionpool.py", line 695, in urlopen
    **response_kw)
  File "/home/p/.local/lib/python3.5/site-packages/telegram/vendor/ptb_urllib3/urllib3/connectionpool.py", line 666, in urlopen
    _stacktrace=sys.exc_info()[2])
  File "/home/p/.local/lib/python3.5/site-packages/telegram/vendor/ptb_urllib3/urllib3/util/retry.py", line 376, in increment
    raise MaxRetryError(_pool, url, error or ResponseError(cause))
telegram.vendor.ptb_urllib3.urllib3.exceptions.MaxRetryError: HTTPSConnectionPool(host='api.telegram.org', port=443): Max retries exceeded with url: /bot504744759:AAFLDudnlMRy7yyp196gpyAqQtbdntWEwkw/setWebhook (Caused by NewConnectionError('<telegram.vendor.ptb_urllib3.urllib3.connection.VerifiedHTTPSConnection object at 0x7fb0f03183c8>: Failed to establish a new connection: [Errno -3] Temporary failure in name resolution',))

During handling of the above exception, another exception occurred:

Traceback (most recent call last):
  File "/home/p/.local/lib/python3.5/site-packages/telegram/ext/updater.py", line 390, in _bootstrap
    url=webhook_url, certificate=cert, allowed_updates=allowed_updates)
  File "/home/p/.local/lib/python3.5/site-packages/telegram/bot.py", line 60, in decorator
    result = func(self, *args, **kwargs)
  File "/home/p/.local/lib/python3.5/site-packages/telegram/bot.py", line 1813, in set_webhook
    result = self._request.post(url_, data, timeout=timeout)
  File "/home/p/.local/lib/python3.5/site-packages/telegram/utils/request.py", line 272, in post
    **urlopen_kwargs)
  File "/home/p/.local/lib/python3.5/site-packages/telegram/utils/request.py", line 196, in _request_wrapper
    raise NetworkError('urllib3 HTTPError {0}'.format(error))
telegram.error.NetworkError: urllib3 HTTPError HTTPSConnectionPool(host='api.telegram.org', port=443): Max retries exceeded with url: /bot504744759:AAFLDudnlMRy7yyp196gpyAqQtbdntWEwkw/setWebhook (Caused by NewConnectionError('<telegram.vendor.ptb_urllib3.urllib3.connection.VerifiedHTTPSConnection object at 0x7fb0f03183c8>: Failed to establish a new connection: [Errno -3] Temporary failure in name resolution',))
telegram.ext.updater - ERROR - unhandled exception
Traceback (most recent call last):
  File "/home/p/.local/lib/python3.5/site-packages/telegram/vendor/ptb_urllib3/urllib3/connection.py", line 141, in _new_conn
    (self.host, self.port), self.timeout, **extra_kw)
  File "/home/p/.local/lib/python3.5/site-packages/telegram/vendor/ptb_urllib3/urllib3/util/connection.py", line 60, in create_connection
    for res in socket.getaddrinfo(host, port, family, socket.SOCK_STREAM):
  File "/usr/lib/python3.5/socket.py", line 732, in getaddrinfo
    for res in _socket.getaddrinfo(host, port, family, type, proto, flags):
socket.gaierror: [Errno -3] Temporary failure in name resolution

During handling of the above exception, another exception occurred:

Traceback (most recent call last):
  File "/home/p/.local/lib/python3.5/site-packages/telegram/vendor/ptb_urllib3/urllib3/connectionpool.py", line 617, in urlopen
    chunked=chunked)
  File "/home/p/.local/lib/python3.5/site-packages/telegram/vendor/ptb_urllib3/urllib3/connectionpool.py", line 360, in _make_request
    self._validate_conn(conn)
  File "/home/p/.local/lib/python3.5/site-packages/telegram/vendor/ptb_urllib3/urllib3/connectionpool.py", line 857, in _validate_conn
    super(HTTPSConnectionPool, self)._validate_conn(conn)
  File "/home/p/.local/lib/python3.5/site-packages/telegram/vendor/ptb_urllib3/urllib3/connectionpool.py", line 289, in _validate_conn
    conn.connect()
  File "/home/p/.local/lib/python3.5/site-packages/telegram/vendor/ptb_urllib3/urllib3/connection.py", line 284, in connect
    conn = self._new_conn()
  File "/home/p/.local/lib/python3.5/site-packages/telegram/vendor/ptb_urllib3/urllib3/connection.py", line 150, in _new_conn
    self, "Failed to establish a new connection: %s" % e)
telegram.vendor.ptb_urllib3.urllib3.exceptions.NewConnectionError: <telegram.vendor.ptb_urllib3.urllib3.connection.VerifiedHTTPSConnection object at 0x7fb0f03183c8>: Failed to establish a new connection: [Errno -3] Temporary failure in name resolution

During handling of the above exception, another exception occurred:

Traceback (most recent call last):
  File "/home/p/.local/lib/python3.5/site-packages/telegram/utils/request.py", line 190, in _request_wrapper
    resp = self._con_pool.request(*args, **kwargs)
  File "/home/p/.local/lib/python3.5/site-packages/telegram/vendor/ptb_urllib3/urllib3/request.py", line 70, in request
    **urlopen_kw)
  File "/home/p/.local/lib/python3.5/site-packages/telegram/vendor/ptb_urllib3/urllib3/request.py", line 148, in request_encode_body
    return self.urlopen(method, url, **extra_kw)
  File "/home/p/.local/lib/python3.5/site-packages/telegram/vendor/ptb_urllib3/urllib3/poolmanager.py", line 244, in urlopen
    response = conn.urlopen(method, u.request_uri, **kw)
  File "/home/p/.local/lib/python3.5/site-packages/telegram/vendor/ptb_urllib3/urllib3/connectionpool.py", line 695, in urlopen
    **response_kw)
  File "/home/p/.local/lib/python3.5/site-packages/telegram/vendor/ptb_urllib3/urllib3/connectionpool.py", line 695, in urlopen
    **response_kw)
  File "/home/p/.local/lib/python3.5/site-packages/telegram/vendor/ptb_urllib3/urllib3/connectionpool.py", line 695, in urlopen
    **response_kw)
  File "/home/p/.local/lib/python3.5/site-packages/telegram/vendor/ptb_urllib3/urllib3/connectionpool.py", line 666, in urlopen
    _stacktrace=sys.exc_info()[2])
  File "/home/p/.local/lib/python3.5/site-packages/telegram/vendor/ptb_urllib3/urllib3/util/retry.py", line 376, in increment
    raise MaxRetryError(_pool, url, error or ResponseError(cause))
telegram.vendor.ptb_urllib3.urllib3.exceptions.MaxRetryError: HTTPSConnectionPool(host='api.telegram.org', port=443): Max retries exceeded with url: /bot504744759:AAFLDudnlMRy7yyp196gpyAqQtbdntWEwkw/setWebhook (Caused by NewConnectionError('<telegram.vendor.ptb_urllib3.urllib3.connection.VerifiedHTTPSConnection object at 0x7fb0f03183c8>: Failed to establish a new connection: [Errno -3] Temporary failure in name resolution',))

During handling of the above exception, another exception occurred:

Traceback (most recent call last):
  File "/home/p/.local/lib/python3.5/site-packages/telegram/ext/updater.py", line 149, in _thread_wrapper
    target(*args, **kwargs)
  File "/home/p/.local/lib/python3.5/site-packages/telegram/ext/updater.py", line 278, in _start_polling
    self._bootstrap(bootstrap_retries, clean=clean, webhook_url='', allowed_updates=None)
  File "/home/p/.local/lib/python3.5/site-packages/telegram/ext/updater.py", line 390, in _bootstrap
    url=webhook_url, certificate=cert, allowed_updates=allowed_updates)
  File "/home/p/.local/lib/python3.5/site-packages/telegram/bot.py", line 60, in decorator
    result = func(self, *args, **kwargs)
  File "/home/p/.local/lib/python3.5/site-packages/telegram/bot.py", line 1813, in set_webhook
    result = self._request.post(url_, data, timeout=timeout)
  File "/home/p/.local/lib/python3.5/site-packages/telegram/utils/request.py", line 272, in post
    **urlopen_kwargs)
  File "/home/p/.local/lib/python3.5/site-packages/telegram/utils/request.py", line 196, in _request_wrapper
    raise NetworkError('urllib3 HTTPError {0}'.format(error))
telegram.error.NetworkError: urllib3 HTTPError HTTPSConnectionPool(host='api.telegram.org', port=443): Max retries exceeded with url: /bot504744759:AAFLDudnlMRy7yyp196gpyAqQtbdntWEwkw/setWebhook (Caused by NewConnectionError('<telegram.vendor.ptb_urllib3.urllib3.connection.VerifiedHTTPSConnection object at 0x7fb0f03183c8>: Failed to establish a new connection: [Errno -3] Temporary failure in name resolution',))
telegram.ext.dispatcher - CRITICAL - stopping due to exception in another thread
telegram.vendor.ptb_urllib3.urllib3.connectionpool - WARNING - Retrying (Retry(total=2, connect=None, read=None, redirect=None)) after connection broken by 'NewConnectionError('<telegram.vendor.ptb_urllib3.urllib3.connection.VerifiedHTTPSConnection object at 0x7f432b51b710>: Failed to establish a new connection: [Errno -3] Temporary failure in name resolution',)': /bot504744759:AAFLDudnlMRy7yyp196gpyAqQtbdntWEwkw/setWebhook
telegram.vendor.ptb_urllib3.urllib3.connectionpool - WARNING - Retrying (Retry(total=1, connect=None, read=None, redirect=None)) after connection broken by 'NewConnectionError('<telegram.vendor.ptb_urllib3.urllib3.connection.VerifiedHTTPSConnection object at 0x7f432b51b438>: Failed to establish a new connection: [Errno -3] Temporary failure in name resolution',)': /bot504744759:AAFLDudnlMRy7yyp196gpyAqQtbdntWEwkw/setWebhook
telegram.vendor.ptb_urllib3.urllib3.connectionpool - WARNING - Retrying (Retry(total=0, connect=None, read=None, redirect=None)) after connection broken by 'NewConnectionError('<telegram.vendor.ptb_urllib3.urllib3.connection.VerifiedHTTPSConnection object at 0x7f432b51bb38>: Failed to establish a new connection: [Errno -3] Temporary failure in name resolution',)': /bot504744759:AAFLDudnlMRy7yyp196gpyAqQtbdntWEwkw/setWebhook
telegram.ext.updater - ERROR - error in bootstrap phase; try=0 max_retries=0
Traceback (most recent call last):
  File "/home/p/.local/lib/python3.5/site-packages/telegram/vendor/ptb_urllib3/urllib3/connection.py", line 141, in _new_conn
    (self.host, self.port), self.timeout, **extra_kw)
  File "/home/p/.local/lib/python3.5/site-packages/telegram/vendor/ptb_urllib3/urllib3/util/connection.py", line 60, in create_connection
    for res in socket.getaddrinfo(host, port, family, socket.SOCK_STREAM):
  File "/usr/lib/python3.5/socket.py", line 732, in getaddrinfo
    for res in _socket.getaddrinfo(host, port, family, type, proto, flags):
socket.gaierror: [Errno -3] Temporary failure in name resolution

During handling of the above exception, another exception occurred:

Traceback (most recent call last):
  File "/home/p/.local/lib/python3.5/site-packages/telegram/vendor/ptb_urllib3/urllib3/connectionpool.py", line 617, in urlopen
    chunked=chunked)
  File "/home/p/.local/lib/python3.5/site-packages/telegram/vendor/ptb_urllib3/urllib3/connectionpool.py", line 360, in _make_request
    self._validate_conn(conn)
  File "/home/p/.local/lib/python3.5/site-packages/telegram/vendor/ptb_urllib3/urllib3/connectionpool.py", line 857, in _validate_conn
    super(HTTPSConnectionPool, self)._validate_conn(conn)
  File "/home/p/.local/lib/python3.5/site-packages/telegram/vendor/ptb_urllib3/urllib3/connectionpool.py", line 289, in _validate_conn
    conn.connect()
  File "/home/p/.local/lib/python3.5/site-packages/telegram/vendor/ptb_urllib3/urllib3/connection.py", line 284, in connect
    conn = self._new_conn()
  File "/home/p/.local/lib/python3.5/site-packages/telegram/vendor/ptb_urllib3/urllib3/connection.py", line 150, in _new_conn
    self, "Failed to establish a new connection: %s" % e)
telegram.vendor.ptb_urllib3.urllib3.exceptions.NewConnectionError: <telegram.vendor.ptb_urllib3.urllib3.connection.VerifiedHTTPSConnection object at 0x7f43284ac320>: Failed to establish a new connection: [Errno -3] Temporary failure in name resolution

During handling of the above exception, another exception occurred:

Traceback (most recent call last):
  File "/home/p/.local/lib/python3.5/site-packages/telegram/utils/request.py", line 190, in _request_wrapper
    resp = self._con_pool.request(*args, **kwargs)
  File "/home/p/.local/lib/python3.5/site-packages/telegram/vendor/ptb_urllib3/urllib3/request.py", line 70, in request
    **urlopen_kw)
  File "/home/p/.local/lib/python3.5/site-packages/telegram/vendor/ptb_urllib3/urllib3/request.py", line 148, in request_encode_body
    return self.urlopen(method, url, **extra_kw)
  File "/home/p/.local/lib/python3.5/site-packages/telegram/vendor/ptb_urllib3/urllib3/poolmanager.py", line 244, in urlopen
    response = conn.urlopen(method, u.request_uri, **kw)
  File "/home/p/.local/lib/python3.5/site-packages/telegram/vendor/ptb_urllib3/urllib3/connectionpool.py", line 695, in urlopen
    **response_kw)
  File "/home/p/.local/lib/python3.5/site-packages/telegram/vendor/ptb_urllib3/urllib3/connectionpool.py", line 695, in urlopen
    **response_kw)
  File "/home/p/.local/lib/python3.5/site-packages/telegram/vendor/ptb_urllib3/urllib3/connectionpool.py", line 695, in urlopen
    **response_kw)
  File "/home/p/.local/lib/python3.5/site-packages/telegram/vendor/ptb_urllib3/urllib3/connectionpool.py", line 666, in urlopen
    _stacktrace=sys.exc_info()[2])
  File "/home/p/.local/lib/python3.5/site-packages/telegram/vendor/ptb_urllib3/urllib3/util/retry.py", line 376, in increment
    raise MaxRetryError(_pool, url, error or ResponseError(cause))
telegram.vendor.ptb_urllib3.urllib3.exceptions.MaxRetryError: HTTPSConnectionPool(host='api.telegram.org', port=443): Max retries exceeded with url: /bot504744759:AAFLDudnlMRy7yyp196gpyAqQtbdntWEwkw/setWebhook (Caused by NewConnectionError('<telegram.vendor.ptb_urllib3.urllib3.connection.VerifiedHTTPSConnection object at 0x7f43284ac320>: Failed to establish a new connection: [Errno -3] Temporary failure in name resolution',))

During handling of the above exception, another exception occurred:

Traceback (most recent call last):
  File "/home/p/.local/lib/python3.5/site-packages/telegram/ext/updater.py", line 390, in _bootstrap
    url=webhook_url, certificate=cert, allowed_updates=allowed_updates)
  File "/home/p/.local/lib/python3.5/site-packages/telegram/bot.py", line 60, in decorator
    result = func(self, *args, **kwargs)
  File "/home/p/.local/lib/python3.5/site-packages/telegram/bot.py", line 1813, in set_webhook
    result = self._request.post(url_, data, timeout=timeout)
  File "/home/p/.local/lib/python3.5/site-packages/telegram/utils/request.py", line 272, in post
    **urlopen_kwargs)
  File "/home/p/.local/lib/python3.5/site-packages/telegram/utils/request.py", line 196, in _request_wrapper
    raise NetworkError('urllib3 HTTPError {0}'.format(error))
telegram.error.NetworkError: urllib3 HTTPError HTTPSConnectionPool(host='api.telegram.org', port=443): Max retries exceeded with url: /bot504744759:AAFLDudnlMRy7yyp196gpyAqQtbdntWEwkw/setWebhook (Caused by NewConnectionError('<telegram.vendor.ptb_urllib3.urllib3.connection.VerifiedHTTPSConnection object at 0x7f43284ac320>: Failed to establish a new connection: [Errno -3] Temporary failure in name resolution',))
telegram.ext.updater - ERROR - unhandled exception
Traceback (most recent call last):
  File "/home/p/.local/lib/python3.5/site-packages/telegram/vendor/ptb_urllib3/urllib3/connection.py", line 141, in _new_conn
    (self.host, self.port), self.timeout, **extra_kw)
  File "/home/p/.local/lib/python3.5/site-packages/telegram/vendor/ptb_urllib3/urllib3/util/connection.py", line 60, in create_connection
    for res in socket.getaddrinfo(host, port, family, socket.SOCK_STREAM):
  File "/usr/lib/python3.5/socket.py", line 732, in getaddrinfo
    for res in _socket.getaddrinfo(host, port, family, type, proto, flags):
socket.gaierror: [Errno -3] Temporary failure in name resolution

During handling of the above exception, another exception occurred:

Traceback (most recent call last):
  File "/home/p/.local/lib/python3.5/site-packages/telegram/vendor/ptb_urllib3/urllib3/connectionpool.py", line 617, in urlopen
    chunked=chunked)
  File "/home/p/.local/lib/python3.5/site-packages/telegram/vendor/ptb_urllib3/urllib3/connectionpool.py", line 360, in _make_request
    self._validate_conn(conn)
  File "/home/p/.local/lib/python3.5/site-packages/telegram/vendor/ptb_urllib3/urllib3/connectionpool.py", line 857, in _validate_conn
    super(HTTPSConnectionPool, self)._validate_conn(conn)
  File "/home/p/.local/lib/python3.5/site-packages/telegram/vendor/ptb_urllib3/urllib3/connectionpool.py", line 289, in _validate_conn
    conn.connect()
  File "/home/p/.local/lib/python3.5/site-packages/telegram/vendor/ptb_urllib3/urllib3/connection.py", line 284, in connect
    conn = self._new_conn()
  File "/home/p/.local/lib/python3.5/site-packages/telegram/vendor/ptb_urllib3/urllib3/connection.py", line 150, in _new_conn
    self, "Failed to establish a new connection: %s" % e)
telegram.vendor.ptb_urllib3.urllib3.exceptions.NewConnectionError: <telegram.vendor.ptb_urllib3.urllib3.connection.VerifiedHTTPSConnection object at 0x7f43284ac320>: Failed to establish a new connection: [Errno -3] Temporary failure in name resolution

During handling of the above exception, another exception occurred:

Traceback (most recent call last):
  File "/home/p/.local/lib/python3.5/site-packages/telegram/utils/request.py", line 190, in _request_wrapper
    resp = self._con_pool.request(*args, **kwargs)
  File "/home/p/.local/lib/python3.5/site-packages/telegram/vendor/ptb_urllib3/urllib3/request.py", line 70, in request
    **urlopen_kw)
  File "/home/p/.local/lib/python3.5/site-packages/telegram/vendor/ptb_urllib3/urllib3/request.py", line 148, in request_encode_body
    return self.urlopen(method, url, **extra_kw)
  File "/home/p/.local/lib/python3.5/site-packages/telegram/vendor/ptb_urllib3/urllib3/poolmanager.py", line 244, in urlopen
    response = conn.urlopen(method, u.request_uri, **kw)
  File "/home/p/.local/lib/python3.5/site-packages/telegram/vendor/ptb_urllib3/urllib3/connectionpool.py", line 695, in urlopen
    **response_kw)
  File "/home/p/.local/lib/python3.5/site-packages/telegram/vendor/ptb_urllib3/urllib3/connectionpool.py", line 695, in urlopen
    **response_kw)
  File "/home/p/.local/lib/python3.5/site-packages/telegram/vendor/ptb_urllib3/urllib3/connectionpool.py", line 695, in urlopen
    **response_kw)
  File "/home/p/.local/lib/python3.5/site-packages/telegram/vendor/ptb_urllib3/urllib3/connectionpool.py", line 666, in urlopen
    _stacktrace=sys.exc_info()[2])
  File "/home/p/.local/lib/python3.5/site-packages/telegram/vendor/ptb_urllib3/urllib3/util/retry.py", line 376, in increment
    raise MaxRetryError(_pool, url, error or ResponseError(cause))
telegram.vendor.ptb_urllib3.urllib3.exceptions.MaxRetryError: HTTPSConnectionPool(host='api.telegram.org', port=443): Max retries exceeded with url: /bot504744759:AAFLDudnlMRy7yyp196gpyAqQtbdntWEwkw/setWebhook (Caused by NewConnectionError('<telegram.vendor.ptb_urllib3.urllib3.connection.VerifiedHTTPSConnection object at 0x7f43284ac320>: Failed to establish a new connection: [Errno -3] Temporary failure in name resolution',))

During handling of the above exception, another exception occurred:

Traceback (most recent call last):
  File "/home/p/.local/lib/python3.5/site-packages/telegram/ext/updater.py", line 149, in _thread_wrapper
    target(*args, **kwargs)
  File "/home/p/.local/lib/python3.5/site-packages/telegram/ext/updater.py", line 278, in _start_polling
    self._bootstrap(bootstrap_retries, clean=clean, webhook_url='', allowed_updates=None)
  File "/home/p/.local/lib/python3.5/site-packages/telegram/ext/updater.py", line 390, in _bootstrap
    url=webhook_url, certificate=cert, allowed_updates=allowed_updates)
  File "/home/p/.local/lib/python3.5/site-packages/telegram/bot.py", line 60, in decorator
    result = func(self, *args, **kwargs)
  File "/home/p/.local/lib/python3.5/site-packages/telegram/bot.py", line 1813, in set_webhook
    result = self._request.post(url_, data, timeout=timeout)
  File "/home/p/.local/lib/python3.5/site-packages/telegram/utils/request.py", line 272, in post
    **urlopen_kwargs)
  File "/home/p/.local/lib/python3.5/site-packages/telegram/utils/request.py", line 196, in _request_wrapper
    raise NetworkError('urllib3 HTTPError {0}'.format(error))
telegram.error.NetworkError: urllib3 HTTPError HTTPSConnectionPool(host='api.telegram.org', port=443): Max retries exceeded with url: /bot504744759:AAFLDudnlMRy7yyp196gpyAqQtbdntWEwkw/setWebhook (Caused by NewConnectionError('<telegram.vendor.ptb_urllib3.urllib3.connection.VerifiedHTTPSConnection object at 0x7f43284ac320>: Failed to establish a new connection: [Errno -3] Temporary failure in name resolution',))
telegram.ext.dispatcher - CRITICAL - stopping due to exception in another thread
telegram.vendor.ptb_urllib3.urllib3.connectionpool - WARNING - Retrying (Retry(total=2, connect=None, read=None, redirect=None)) after connection broken by 'NewConnectionError('<telegram.vendor.ptb_urllib3.urllib3.connection.VerifiedHTTPSConnection object at 0x7f2851ae2b00>: Failed to establish a new connection: [Errno -3] Temporary failure in name resolution',)': /bot504744759:AAFLDudnlMRy7yyp196gpyAqQtbdntWEwkw/setWebhook
telegram.vendor.ptb_urllib3.urllib3.connectionpool - WARNING - Retrying (Retry(total=1, connect=None, read=None, redirect=None)) after connection broken by 'NewConnectionError('<telegram.vendor.ptb_urllib3.urllib3.connection.VerifiedHTTPSConnection object at 0x7f2851ae2b70>: Failed to establish a new connection: [Errno -3] Temporary failure in name resolution',)': /bot504744759:AAFLDudnlMRy7yyp196gpyAqQtbdntWEwkw/setWebhook
telegram.vendor.ptb_urllib3.urllib3.connectionpool - WARNING - Retrying (Retry(total=0, connect=None, read=None, redirect=None)) after connection broken by 'NewConnectionError('<telegram.vendor.ptb_urllib3.urllib3.connection.VerifiedHTTPSConnection object at 0x7f2851ae2be0>: Failed to establish a new connection: [Errno -3] Temporary failure in name resolution',)': /bot504744759:AAFLDudnlMRy7yyp196gpyAqQtbdntWEwkw/setWebhook
telegram.ext.updater - ERROR - error in bootstrap phase; try=0 max_retries=0
Traceback (most recent call last):
  File "/home/p/.local/lib/python3.5/site-packages/telegram/vendor/ptb_urllib3/urllib3/connection.py", line 141, in _new_conn
    (self.host, self.port), self.timeout, **extra_kw)
  File "/home/p/.local/lib/python3.5/site-packages/telegram/vendor/ptb_urllib3/urllib3/util/connection.py", line 60, in create_connection
    for res in socket.getaddrinfo(host, port, family, socket.SOCK_STREAM):
  File "/usr/lib/python3.5/socket.py", line 732, in getaddrinfo
    for res in _socket.getaddrinfo(host, port, family, type, proto, flags):
socket.gaierror: [Errno -3] Temporary failure in name resolution

During handling of the above exception, another exception occurred:

Traceback (most recent call last):
  File "/home/p/.local/lib/python3.5/site-packages/telegram/vendor/ptb_urllib3/urllib3/connectionpool.py", line 617, in urlopen
    chunked=chunked)
  File "/home/p/.local/lib/python3.5/site-packages/telegram/vendor/ptb_urllib3/urllib3/connectionpool.py", line 360, in _make_request
    self._validate_conn(conn)
  File "/home/p/.local/lib/python3.5/site-packages/telegram/vendor/ptb_urllib3/urllib3/connectionpool.py", line 857, in _validate_conn
    super(HTTPSConnectionPool, self)._validate_conn(conn)
  File "/home/p/.local/lib/python3.5/site-packages/telegram/vendor/ptb_urllib3/urllib3/connectionpool.py", line 289, in _validate_conn
    conn.connect()
  File "/home/p/.local/lib/python3.5/site-packages/telegram/vendor/ptb_urllib3/urllib3/connection.py", line 284, in connect
    conn = self._new_conn()
  File "/home/p/.local/lib/python3.5/site-packages/telegram/vendor/ptb_urllib3/urllib3/connection.py", line 150, in _new_conn
    self, "Failed to establish a new connection: %s" % e)
telegram.vendor.ptb_urllib3.urllib3.exceptions.NewConnectionError: <telegram.vendor.ptb_urllib3.urllib3.connection.VerifiedHTTPSConnection object at 0x7f285027a780>: Failed to establish a new connection: [Errno -3] Temporary failure in name resolution

During handling of the above exception, another exception occurred:

Traceback (most recent call last):
  File "/home/p/.local/lib/python3.5/site-packages/telegram/utils/request.py", line 190, in _request_wrapper
    resp = self._con_pool.request(*args, **kwargs)
  File "/home/p/.local/lib/python3.5/site-packages/telegram/vendor/ptb_urllib3/urllib3/request.py", line 70, in request
    **urlopen_kw)
  File "/home/p/.local/lib/python3.5/site-packages/telegram/vendor/ptb_urllib3/urllib3/request.py", line 148, in request_encode_body
    return self.urlopen(method, url, **extra_kw)
  File "/home/p/.local/lib/python3.5/site-packages/telegram/vendor/ptb_urllib3/urllib3/poolmanager.py", line 244, in urlopen
    response = conn.urlopen(method, u.request_uri, **kw)
  File "/home/p/.local/lib/python3.5/site-packages/telegram/vendor/ptb_urllib3/urllib3/connectionpool.py", line 695, in urlopen
    **response_kw)
  File "/home/p/.local/lib/python3.5/site-packages/telegram/vendor/ptb_urllib3/urllib3/connectionpool.py", line 695, in urlopen
    **response_kw)
  File "/home/p/.local/lib/python3.5/site-packages/telegram/vendor/ptb_urllib3/urllib3/connectionpool.py", line 695, in urlopen
    **response_kw)
  File "/home/p/.local/lib/python3.5/site-packages/telegram/vendor/ptb_urllib3/urllib3/connectionpool.py", line 666, in urlopen
    _stacktrace=sys.exc_info()[2])
  File "/home/p/.local/lib/python3.5/site-packages/telegram/vendor/ptb_urllib3/urllib3/util/retry.py", line 376, in increment
    raise MaxRetryError(_pool, url, error or ResponseError(cause))
telegram.vendor.ptb_urllib3.urllib3.exceptions.MaxRetryError: HTTPSConnectionPool(host='api.telegram.org', port=443): Max retries exceeded with url: /bot504744759:AAFLDudnlMRy7yyp196gpyAqQtbdntWEwkw/setWebhook (Caused by NewConnectionError('<telegram.vendor.ptb_urllib3.urllib3.connection.VerifiedHTTPSConnection object at 0x7f285027a780>: Failed to establish a new connection: [Errno -3] Temporary failure in name resolution',))

During handling of the above exception, another exception occurred:

Traceback (most recent call last):
  File "/home/p/.local/lib/python3.5/site-packages/telegram/ext/updater.py", line 390, in _bootstrap
    url=webhook_url, certificate=cert, allowed_updates=allowed_updates)
  File "/home/p/.local/lib/python3.5/site-packages/telegram/bot.py", line 60, in decorator
    result = func(self, *args, **kwargs)
  File "/home/p/.local/lib/python3.5/site-packages/telegram/bot.py", line 1813, in set_webhook
    result = self._request.post(url_, data, timeout=timeout)
  File "/home/p/.local/lib/python3.5/site-packages/telegram/utils/request.py", line 272, in post
    **urlopen_kwargs)
  File "/home/p/.local/lib/python3.5/site-packages/telegram/utils/request.py", line 196, in _request_wrapper
    raise NetworkError('urllib3 HTTPError {0}'.format(error))
telegram.error.NetworkError: urllib3 HTTPError HTTPSConnectionPool(host='api.telegram.org', port=443): Max retries exceeded with url: /bot504744759:AAFLDudnlMRy7yyp196gpyAqQtbdntWEwkw/setWebhook (Caused by NewConnectionError('<telegram.vendor.ptb_urllib3.urllib3.connection.VerifiedHTTPSConnection object at 0x7f285027a780>: Failed to establish a new connection: [Errno -3] Temporary failure in name resolution',))
telegram.ext.updater - ERROR - unhandled exception
Traceback (most recent call last):
  File "/home/p/.local/lib/python3.5/site-packages/telegram/vendor/ptb_urllib3/urllib3/connection.py", line 141, in _new_conn
    (self.host, self.port), self.timeout, **extra_kw)
  File "/home/p/.local/lib/python3.5/site-packages/telegram/vendor/ptb_urllib3/urllib3/util/connection.py", line 60, in create_connection
    for res in socket.getaddrinfo(host, port, family, socket.SOCK_STREAM):
  File "/usr/lib/python3.5/socket.py", line 732, in getaddrinfo
    for res in _socket.getaddrinfo(host, port, family, type, proto, flags):
socket.gaierror: [Errno -3] Temporary failure in name resolution

During handling of the above exception, another exception occurred:

Traceback (most recent call last):
  File "/home/p/.local/lib/python3.5/site-packages/telegram/vendor/ptb_urllib3/urllib3/connectionpool.py", line 617, in urlopen
    chunked=chunked)
  File "/home/p/.local/lib/python3.5/site-packages/telegram/vendor/ptb_urllib3/urllib3/connectionpool.py", line 360, in _make_request
    self._validate_conn(conn)
  File "/home/p/.local/lib/python3.5/site-packages/telegram/vendor/ptb_urllib3/urllib3/connectionpool.py", line 857, in _validate_conn
    super(HTTPSConnectionPool, self)._validate_conn(conn)
  File "/home/p/.local/lib/python3.5/site-packages/telegram/vendor/ptb_urllib3/urllib3/connectionpool.py", line 289, in _validate_conn
    conn.connect()
  File "/home/p/.local/lib/python3.5/site-packages/telegram/vendor/ptb_urllib3/urllib3/connection.py", line 284, in connect
    conn = self._new_conn()
  File "/home/p/.local/lib/python3.5/site-packages/telegram/vendor/ptb_urllib3/urllib3/connection.py", line 150, in _new_conn
    self, "Failed to establish a new connection: %s" % e)
telegram.vendor.ptb_urllib3.urllib3.exceptions.NewConnectionError: <telegram.vendor.ptb_urllib3.urllib3.connection.VerifiedHTTPSConnection object at 0x7f285027a780>: Failed to establish a new connection: [Errno -3] Temporary failure in name resolution

During handling of the above exception, another exception occurred:

Traceback (most recent call last):
  File "/home/p/.local/lib/python3.5/site-packages/telegram/utils/request.py", line 190, in _request_wrapper
    resp = self._con_pool.request(*args, **kwargs)
  File "/home/p/.local/lib/python3.5/site-packages/telegram/vendor/ptb_urllib3/urllib3/request.py", line 70, in request
    **urlopen_kw)
  File "/home/p/.local/lib/python3.5/site-packages/telegram/vendor/ptb_urllib3/urllib3/request.py", line 148, in request_encode_body
    return self.urlopen(method, url, **extra_kw)
  File "/home/p/.local/lib/python3.5/site-packages/telegram/vendor/ptb_urllib3/urllib3/poolmanager.py", line 244, in urlopen
    response = conn.urlopen(method, u.request_uri, **kw)
  File "/home/p/.local/lib/python3.5/site-packages/telegram/vendor/ptb_urllib3/urllib3/connectionpool.py", line 695, in urlopen
    **response_kw)
  File "/home/p/.local/lib/python3.5/site-packages/telegram/vendor/ptb_urllib3/urllib3/connectionpool.py", line 695, in urlopen
    **response_kw)
  File "/home/p/.local/lib/python3.5/site-packages/telegram/vendor/ptb_urllib3/urllib3/connectionpool.py", line 695, in urlopen
    **response_kw)
  File "/home/p/.local/lib/python3.5/site-packages/telegram/vendor/ptb_urllib3/urllib3/connectionpool.py", line 666, in urlopen
    _stacktrace=sys.exc_info()[2])
  File "/home/p/.local/lib/python3.5/site-packages/telegram/vendor/ptb_urllib3/urllib3/util/retry.py", line 376, in increment
    raise MaxRetryError(_pool, url, error or ResponseError(cause))
telegram.vendor.ptb_urllib3.urllib3.exceptions.MaxRetryError: HTTPSConnectionPool(host='api.telegram.org', port=443): Max retries exceeded with url: /bot504744759:AAFLDudnlMRy7yyp196gpyAqQtbdntWEwkw/setWebhook (Caused by NewConnectionError('<telegram.vendor.ptb_urllib3.urllib3.connection.VerifiedHTTPSConnection object at 0x7f285027a780>: Failed to establish a new connection: [Errno -3] Temporary failure in name resolution',))

During handling of the above exception, another exception occurred:

Traceback (most recent call last):
  File "/home/p/.local/lib/python3.5/site-packages/telegram/ext/updater.py", line 149, in _thread_wrapper
    target(*args, **kwargs)
  File "/home/p/.local/lib/python3.5/site-packages/telegram/ext/updater.py", line 278, in _start_polling
    self._bootstrap(bootstrap_retries, clean=clean, webhook_url='', allowed_updates=None)
  File "/home/p/.local/lib/python3.5/site-packages/telegram/ext/updater.py", line 390, in _bootstrap
    url=webhook_url, certificate=cert, allowed_updates=allowed_updates)
  File "/home/p/.local/lib/python3.5/site-packages/telegram/bot.py", line 60, in decorator
    result = func(self, *args, **kwargs)
  File "/home/p/.local/lib/python3.5/site-packages/telegram/bot.py", line 1813, in set_webhook
    result = self._request.post(url_, data, timeout=timeout)
  File "/home/p/.local/lib/python3.5/site-packages/telegram/utils/request.py", line 272, in post
    **urlopen_kwargs)
  File "/home/p/.local/lib/python3.5/site-packages/telegram/utils/request.py", line 196, in _request_wrapper
    raise NetworkError('urllib3 HTTPError {0}'.format(error))
telegram.error.NetworkError: urllib3 HTTPError HTTPSConnectionPool(host='api.telegram.org', port=443): Max retries exceeded with url: /bot504744759:AAFLDudnlMRy7yyp196gpyAqQtbdntWEwkw/setWebhook (Caused by NewConnectionError('<telegram.vendor.ptb_urllib3.urllib3.connection.VerifiedHTTPSConnection object at 0x7f285027a780>: Failed to establish a new connection: [Errno -3] Temporary failure in name resolution',))
telegram.ext.dispatcher - CRITICAL - stopping due to exception in another thread
telegram.ext.dispatcher - ERROR - An uncaught error was raised while processing the update
Traceback (most recent call last):
  File "/home/p/.local/lib/python3.5/site-packages/telegram/ext/dispatcher.py", line 279, in process_update
    handler.handle_update(update, self)
  File "/home/p/.local/lib/python3.5/site-packages/telegram/ext/commandhandler.py", line 171, in handle_update
    return self.callback(dispatcher.bot, update, **optional_args)
  File "bot.py", line 23, in planet
    location = constellation(user_text('2017'))
TypeError: 'str' object is not callable
telegram.ext.updater - ERROR - Error while getting Updates: Timed out
telegram.ext.dispatcher - ERROR - No error handlers are registered, logging exception...
Traceback (most recent call last):
  File "/home/p/.local/lib/python3.5/site-packages/telegram/vendor/ptb_urllib3/urllib3/connectionpool.py", line 402, in _make_request
    six.raise_from(e, None)
  File "<string>", line 2, in raise_from
  File "/home/p/.local/lib/python3.5/site-packages/telegram/vendor/ptb_urllib3/urllib3/connectionpool.py", line 398, in _make_request
    httplib_response = conn.getresponse()
  File "/usr/lib/python3.5/http/client.py", line 1197, in getresponse
    response.begin()
  File "/usr/lib/python3.5/http/client.py", line 297, in begin
    version, status, reason = self._read_status()
  File "/usr/lib/python3.5/http/client.py", line 258, in _read_status
    line = str(self.fp.readline(_MAXLINE + 1), "iso-8859-1")
  File "/usr/lib/python3.5/socket.py", line 575, in readinto
    return self._sock.recv_into(b)
  File "/usr/lib/python3.5/ssl.py", line 929, in recv_into
    return self.read(nbytes, buffer)
  File "/usr/lib/python3.5/ssl.py", line 791, in read
    return self._sslobj.read(len, buffer)
  File "/usr/lib/python3.5/ssl.py", line 575, in read
    v = self._sslobj.read(len, buffer)
socket.timeout: The read operation timed out

During handling of the above exception, another exception occurred:

Traceback (most recent call last):
  File "/home/p/.local/lib/python3.5/site-packages/telegram/utils/request.py", line 190, in _request_wrapper
    resp = self._con_pool.request(*args, **kwargs)
  File "/home/p/.local/lib/python3.5/site-packages/telegram/vendor/ptb_urllib3/urllib3/request.py", line 70, in request
    **urlopen_kw)
  File "/home/p/.local/lib/python3.5/site-packages/telegram/vendor/ptb_urllib3/urllib3/request.py", line 148, in request_encode_body
    return self.urlopen(method, url, **extra_kw)
  File "/home/p/.local/lib/python3.5/site-packages/telegram/vendor/ptb_urllib3/urllib3/poolmanager.py", line 244, in urlopen
    response = conn.urlopen(method, u.request_uri, **kw)
  File "/home/p/.local/lib/python3.5/site-packages/telegram/vendor/ptb_urllib3/urllib3/connectionpool.py", line 666, in urlopen
    _stacktrace=sys.exc_info()[2])
  File "/home/p/.local/lib/python3.5/site-packages/telegram/vendor/ptb_urllib3/urllib3/util/retry.py", line 347, in increment
    raise six.reraise(type(error), error, _stacktrace)
  File "/home/p/.local/lib/python3.5/site-packages/telegram/vendor/ptb_urllib3/urllib3/packages/six.py", line 686, in reraise
    raise value
  File "/home/p/.local/lib/python3.5/site-packages/telegram/vendor/ptb_urllib3/urllib3/connectionpool.py", line 617, in urlopen
    chunked=chunked)
  File "/home/p/.local/lib/python3.5/site-packages/telegram/vendor/ptb_urllib3/urllib3/connectionpool.py", line 405, in _make_request
    exc_cls=ReadTimeoutError)
  File "/home/p/.local/lib/python3.5/site-packages/telegram/vendor/ptb_urllib3/urllib3/connectionpool.py", line 321, in _raise_timeout
    raise exc_cls(*args)
telegram.vendor.ptb_urllib3.urllib3.exceptions.ReadTimeoutError: HTTPSConnectionPool(host='api.telegram.org', port=443): Read timed out. (read timeout=12.0)

During handling of the above exception, another exception occurred:

Traceback (most recent call last):
  File "/home/p/.local/lib/python3.5/site-packages/telegram/ext/updater.py", line 286, in _start_polling
    allowed_updates=allowed_updates)
  File "/home/p/.local/lib/python3.5/site-packages/telegram/bot.py", line 60, in decorator
    result = func(self, *args, **kwargs)
  File "/home/p/.local/lib/python3.5/site-packages/telegram/bot.py", line 1720, in get_updates
    result = self._request.post(url, data, timeout=float(read_latency) + float(timeout))
  File "/home/p/.local/lib/python3.5/site-packages/telegram/utils/request.py", line 272, in post
    **urlopen_kwargs)
  File "/home/p/.local/lib/python3.5/site-packages/telegram/utils/request.py", line 192, in _request_wrapper
    raise TimedOut()
telegram.error.TimedOut: Timed out
telegram.ext.updater - ERROR - Error while getting Updates: Timed out
telegram.ext.dispatcher - ERROR - No error handlers are registered, logging exception...
Traceback (most recent call last):
  File "/home/p/.local/lib/python3.5/site-packages/telegram/vendor/ptb_urllib3/urllib3/connectionpool.py", line 402, in _make_request
    six.raise_from(e, None)
  File "<string>", line 2, in raise_from
  File "/home/p/.local/lib/python3.5/site-packages/telegram/vendor/ptb_urllib3/urllib3/connectionpool.py", line 398, in _make_request
    httplib_response = conn.getresponse()
  File "/usr/lib/python3.5/http/client.py", line 1197, in getresponse
    response.begin()
  File "/usr/lib/python3.5/http/client.py", line 297, in begin
    version, status, reason = self._read_status()
  File "/usr/lib/python3.5/http/client.py", line 258, in _read_status
    line = str(self.fp.readline(_MAXLINE + 1), "iso-8859-1")
  File "/usr/lib/python3.5/socket.py", line 575, in readinto
    return self._sock.recv_into(b)
  File "/usr/lib/python3.5/ssl.py", line 929, in recv_into
    return self.read(nbytes, buffer)
  File "/usr/lib/python3.5/ssl.py", line 791, in read
    return self._sslobj.read(len, buffer)
  File "/usr/lib/python3.5/ssl.py", line 575, in read
    v = self._sslobj.read(len, buffer)
socket.timeout: The read operation timed out

During handling of the above exception, another exception occurred:

Traceback (most recent call last):
  File "/home/p/.local/lib/python3.5/site-packages/telegram/utils/request.py", line 190, in _request_wrapper
    resp = self._con_pool.request(*args, **kwargs)
  File "/home/p/.local/lib/python3.5/site-packages/telegram/vendor/ptb_urllib3/urllib3/request.py", line 70, in request
    **urlopen_kw)
  File "/home/p/.local/lib/python3.5/site-packages/telegram/vendor/ptb_urllib3/urllib3/request.py", line 148, in request_encode_body
    return self.urlopen(method, url, **extra_kw)
  File "/home/p/.local/lib/python3.5/site-packages/telegram/vendor/ptb_urllib3/urllib3/poolmanager.py", line 244, in urlopen
    response = conn.urlopen(method, u.request_uri, **kw)
  File "/home/p/.local/lib/python3.5/site-packages/telegram/vendor/ptb_urllib3/urllib3/connectionpool.py", line 666, in urlopen
    _stacktrace=sys.exc_info()[2])
  File "/home/p/.local/lib/python3.5/site-packages/telegram/vendor/ptb_urllib3/urllib3/util/retry.py", line 347, in increment
    raise six.reraise(type(error), error, _stacktrace)
  File "/home/p/.local/lib/python3.5/site-packages/telegram/vendor/ptb_urllib3/urllib3/packages/six.py", line 686, in reraise
    raise value
  File "/home/p/.local/lib/python3.5/site-packages/telegram/vendor/ptb_urllib3/urllib3/connectionpool.py", line 617, in urlopen
    chunked=chunked)
  File "/home/p/.local/lib/python3.5/site-packages/telegram/vendor/ptb_urllib3/urllib3/connectionpool.py", line 405, in _make_request
    exc_cls=ReadTimeoutError)
  File "/home/p/.local/lib/python3.5/site-packages/telegram/vendor/ptb_urllib3/urllib3/connectionpool.py", line 321, in _raise_timeout
    raise exc_cls(*args)
telegram.vendor.ptb_urllib3.urllib3.exceptions.ReadTimeoutError: HTTPSConnectionPool(host='api.telegram.org', port=443): Read timed out. (read timeout=12.0)

During handling of the above exception, another exception occurred:

Traceback (most recent call last):
  File "/home/p/.local/lib/python3.5/site-packages/telegram/ext/updater.py", line 286, in _start_polling
    allowed_updates=allowed_updates)
  File "/home/p/.local/lib/python3.5/site-packages/telegram/bot.py", line 60, in decorator
    result = func(self, *args, **kwargs)
  File "/home/p/.local/lib/python3.5/site-packages/telegram/bot.py", line 1720, in get_updates
    result = self._request.post(url, data, timeout=float(read_latency) + float(timeout))
  File "/home/p/.local/lib/python3.5/site-packages/telegram/utils/request.py", line 272, in post
    **urlopen_kwargs)
  File "/home/p/.local/lib/python3.5/site-packages/telegram/utils/request.py", line 192, in _request_wrapper
    raise TimedOut()
telegram.error.TimedOut: Timed out
telegram.ext.dispatcher - ERROR - An uncaught error was raised while processing the update
Traceback (most recent call last):
  File "/home/p/.local/lib/python3.5/site-packages/telegram/ext/dispatcher.py", line 279, in process_update
    handler.handle_update(update, self)
  File "/home/p/.local/lib/python3.5/site-packages/telegram/ext/commandhandler.py", line 171, in handle_update
    return self.callback(dispatcher.bot, update, **optional_args)
  File "bot.py", line 23, in planet
    location = constellation(user_text('2017'))
TypeError: 'str' object is not callable
telegram.ext.dispatcher - ERROR - An uncaught error was raised while processing the update
Traceback (most recent call last):
  File "/home/p/.local/lib/python3.5/site-packages/telegram/ext/dispatcher.py", line 279, in process_update
    handler.handle_update(update, self)
  File "/home/p/.local/lib/python3.5/site-packages/telegram/ext/messagehandler.py", line 169, in handle_update
    return self.callback(dispatcher.bot, update, **optional_args)
  File "bot.py", line 23, in planet
    location = constellation(user_text('2017'))
TypeError: 'str' object is not callable
telegram.ext.dispatcher - ERROR - An uncaught error was raised while processing the update
Traceback (most recent call last):
  File "/home/p/.local/lib/python3.5/site-packages/telegram/ext/dispatcher.py", line 279, in process_update
    handler.handle_update(update, self)
  File "/home/p/.local/lib/python3.5/site-packages/telegram/ext/commandhandler.py", line 171, in handle_update
    return self.callback(dispatcher.bot, update, **optional_args)
  File "bot.py", line 23, in planet
    location = constellation(user_text('2017'))
TypeError: 'str' object is not callable
telegram.ext.dispatcher - ERROR - An uncaught error was raised while processing the update
Traceback (most recent call last):
  File "/home/p/.local/lib/python3.5/site-packages/telegram/ext/dispatcher.py", line 279, in process_update
    handler.handle_update(update, self)
  File "/home/p/.local/lib/python3.5/site-packages/telegram/ext/messagehandler.py", line 169, in handle_update
    return self.callback(dispatcher.bot, update, **optional_args)
  File "bot.py", line 23, in planet
    location = constellation(user_text('2017'))
TypeError: 'str' object is not callable
telegram.ext.dispatcher - ERROR - An uncaught error was raised while processing the update
Traceback (most recent call last):
  File "/home/p/.local/lib/python3.5/site-packages/telegram/ext/dispatcher.py", line 279, in process_update
    handler.handle_update(update, self)
  File "/home/p/.local/lib/python3.5/site-packages/telegram/ext/messagehandler.py", line 169, in handle_update
    return self.callback(dispatcher.bot, update, **optional_args)
  File "bot.py", line 26, in planet
    location = constellation(planet_function('2017'))
NameError: name 'planet_function' is not defined
telegram.ext.dispatcher - ERROR - An uncaught error was raised while processing the update
Traceback (most recent call last):
  File "/home/p/.local/lib/python3.5/site-packages/telegram/ext/dispatcher.py", line 279, in process_update
    handler.handle_update(update, self)
  File "/home/p/.local/lib/python3.5/site-packages/telegram/ext/messagehandler.py", line 169, in handle_update
    return self.callback(dispatcher.bot, update, **optional_args)
  File "bot.py", line 25, in planet
    location = constellation(planet_function('2017'))
NameError: name 'planet_function' is not defined
telegram.ext.dispatcher - ERROR - An uncaught error was raised while processing the update
Traceback (most recent call last):
  File "/home/p/.local/lib/python3.5/site-packages/telegram/ext/dispatcher.py", line 279, in process_update
    handler.handle_update(update, self)
  File "/home/p/.local/lib/python3.5/site-packages/telegram/ext/messagehandler.py", line 169, in handle_update
    return self.callback(dispatcher.bot, update, **optional_args)
  File "bot.py", line 25, in planet
    location = constellation(planet_function('2017'))
NameError: name 'planet_function' is not defined
telegram.ext.dispatcher - ERROR - An uncaught error was raised while processing the update
Traceback (most recent call last):
  File "/home/p/.local/lib/python3.5/site-packages/telegram/ext/dispatcher.py", line 279, in process_update
    handler.handle_update(update, self)
  File "/home/p/.local/lib/python3.5/site-packages/telegram/ext/messagehandler.py", line 169, in handle_update
    return self.callback(dispatcher.bot, update, **optional_args)
  File "bot.py", line 26, in planet
    location = constellation(planet_function('2017'))
NameError: name 'planet_function' is not defined
telegram.ext.dispatcher - ERROR - An uncaught error was raised while processing the update
Traceback (most recent call last):
  File "/home/p/.local/lib/python3.5/site-packages/telegram/ext/dispatcher.py", line 279, in process_update
    handler.handle_update(update, self)
  File "/home/p/.local/lib/python3.5/site-packages/telegram/ext/messagehandler.py", line 169, in handle_update
    return self.callback(dispatcher.bot, update, **optional_args)
  File "bot.py", line 26, in planet
    location = constellation(planet_function('2017'))
NameError: name 'planet_function' is not defined
telegram.ext.dispatcher - ERROR - An uncaught error was raised while processing the update
Traceback (most recent call last):
  File "/home/p/.local/lib/python3.5/site-packages/telegram/ext/dispatcher.py", line 279, in process_update
    handler.handle_update(update, self)
  File "/home/p/.local/lib/python3.5/site-packages/telegram/ext/messagehandler.py", line 169, in handle_update
    return self.callback(dispatcher.bot, update, **optional_args)
  File "bot.py", line 26, in planet
    location = constellation(planet_function('2017'))
NameError: name 'planet_function' is not defined
telegram.ext.dispatcher - ERROR - An uncaught error was raised while processing the update
Traceback (most recent call last):
  File "/home/p/.local/lib/python3.5/site-packages/telegram/ext/dispatcher.py", line 279, in process_update
    handler.handle_update(update, self)
  File "/home/p/.local/lib/python3.5/site-packages/telegram/ext/messagehandler.py", line 169, in handle_update
    return self.callback(dispatcher.bot, update, **optional_args)
  File "bot.py", line 25, in planet
    location = constellation(planet_function('2017'))
NameError: name 'planet_function' is not defined
telegram.ext.dispatcher - ERROR - An uncaught error was raised while processing the update
Traceback (most recent call last):
  File "/home/p/.local/lib/python3.5/site-packages/telegram/ext/dispatcher.py", line 279, in process_update
    handler.handle_update(update, self)
  File "/home/p/.local/lib/python3.5/site-packages/telegram/ext/messagehandler.py", line 169, in handle_update
    return self.callback(dispatcher.bot, update, **optional_args)
  File "bot.py", line 25, in planet
    location = str(constellation(planet_function('2017')))
NameError: name 'planet_function' is not defined
telegram.ext.dispatcher - ERROR - An uncaught error was raised while processing the update
Traceback (most recent call last):
  File "/home/p/.local/lib/python3.5/site-packages/telegram/ext/dispatcher.py", line 279, in process_update
    handler.handle_update(update, self)
  File "/home/p/.local/lib/python3.5/site-packages/telegram/ext/messagehandler.py", line 169, in handle_update
    return self.callback(dispatcher.bot, update, **optional_args)
  File "bot.py", line 25, in planet
    location = str(constellation(planet_function('2017')))
NameError: name 'planet_function' is not defined
telegram.ext.dispatcher - ERROR - An uncaught error was raised while processing the update
Traceback (most recent call last):
  File "/home/p/.local/lib/python3.5/site-packages/telegram/ext/dispatcher.py", line 279, in process_update
    handler.handle_update(update, self)
  File "/home/p/.local/lib/python3.5/site-packages/telegram/ext/messagehandler.py", line 169, in handle_update
    return self.callback(dispatcher.bot, update, **optional_args)
  File "bot.py", line 24, in planet
    location = str(constellation(planet_function('2017')))
NameError: name 'planet_function' is not defined
telegram.ext.dispatcher - ERROR - An uncaught error was raised while processing the update
Traceback (most recent call last):
  File "/home/p/.local/lib/python3.5/site-packages/telegram/ext/dispatcher.py", line 279, in process_update
    handler.handle_update(update, self)
  File "/home/p/.local/lib/python3.5/site-packages/telegram/ext/messagehandler.py", line 169, in handle_update
    return self.callback(dispatcher.bot, update, **optional_args)
  File "bot.py", line 24, in planet
    location = constellation(m('now'))
ValueError: your date string  does not look like a year/month/day optionally followed by hours:minutes:seconds
telegram.ext.dispatcher - ERROR - An uncaught error was raised while processing the update
Traceback (most recent call last):
  File "/home/p/.local/lib/python3.5/site-packages/telegram/ext/dispatcher.py", line 279, in process_update
    handler.handle_update(update, self)
  File "/home/p/.local/lib/python3.5/site-packages/telegram/ext/messagehandler.py", line 169, in handle_update
    return self.callback(dispatcher.bot, update, **optional_args)
  File "bot.py", line 24, in planet
    location = constellation(m('Date'))
ValueError: your date string  does not look like a year/month/day optionally followed by hours:minutes:seconds
telegram.ext.dispatcher - ERROR - An uncaught error was raised while processing the update
Traceback (most recent call last):
  File "/home/p/.local/lib/python3.5/site-packages/telegram/ext/dispatcher.py", line 279, in process_update
    handler.handle_update(update, self)
  File "/home/p/.local/lib/python3.5/site-packages/telegram/ext/messagehandler.py", line 169, in handle_update
    return self.callback(dispatcher.bot, update, **optional_args)
  File "bot.py", line 25, in planet
    'Earth' : Earth,
NameError: name 'Earth' is not defined
telegram.ext.dispatcher - ERROR - An uncaught error was raised while processing the update
Traceback (most recent call last):
  File "/home/p/.local/lib/python3.5/site-packages/telegram/ext/dispatcher.py", line 279, in process_update
    handler.handle_update(update, self)
  File "/home/p/.local/lib/python3.5/site-packages/telegram/ext/messagehandler.py", line 169, in handle_update
    return self.callback(dispatcher.bot, update, **optional_args)
  File "bot.py", line 25, in planet
    'Earth' : Earth,
NameError: name 'Earth' is not defined
telegram.ext.dispatcher - ERROR - An uncaught error was raised while processing the update
Traceback (most recent call last):
  File "/home/p/.local/lib/python3.5/site-packages/telegram/ext/dispatcher.py", line 279, in process_update
    handler.handle_update(update, self)
  File "/home/p/.local/lib/python3.5/site-packages/telegram/ext/messagehandler.py", line 169, in handle_update
    return self.callback(dispatcher.bot, update, **optional_args)
  File "bot.py", line 25, in planet
    'Earth' : Earth,
NameError: name 'Earth' is not defined
telegram.ext.dispatcher - ERROR - An uncaught error was raised while processing the update
Traceback (most recent call last):
  File "/home/p/.local/lib/python3.5/site-packages/telegram/ext/dispatcher.py", line 279, in process_update
    handler.handle_update(update, self)
  File "/home/p/.local/lib/python3.5/site-packages/telegram/ext/messagehandler.py", line 169, in handle_update
    return self.callback(dispatcher.bot, update, **optional_args)
  File "bot.py", line 23, in planet
    'Mercury' : Mercury, 'Moon': Moon, 'Venus': Venus, 'Earth' : Earth, 'Mars' : Mars, 'Jupiter' : Jupiter, 'Saturn' : Saturn, 'Uranus' : Uranus, 'Neptune' : Neptune, 'Pluto' : Pluto, 'Sun' : Sun, 'Moon' : Moon}
NameError: name 'Earth' is not defined
telegram.ext.dispatcher - ERROR - An uncaught error was raised while processing the update
Traceback (most recent call last):
  File "/home/p/.local/lib/python3.5/site-packages/telegram/ext/dispatcher.py", line 279, in process_update
    handler.handle_update(update, self)
  File "/home/p/.local/lib/python3.5/site-packages/telegram/ext/messagehandler.py", line 169, in handle_update
    return self.callback(dispatcher.bot, update, **optional_args)
  File "bot.py", line 25, in planet
    'Earth' : Earth,
NameError: name 'Earth' is not defined
telegram.ext.dispatcher - ERROR - An uncaught error was raised while processing the update
Traceback (most recent call last):
  File "/home/p/.local/lib/python3.5/site-packages/telegram/ext/dispatcher.py", line 279, in process_update
    handler.handle_update(update, self)
  File "/home/p/.local/lib/python3.5/site-packages/telegram/ext/messagehandler.py", line 169, in handle_update
    return self.callback(dispatcher.bot, update, **optional_args)
  File "bot.py", line 25, in planet
    'Earth' : Earth,
NameError: name 'Earth' is not defined
telegram.ext.dispatcher - ERROR - An uncaught error was raised while processing the update
Traceback (most recent call last):
  File "/home/p/.local/lib/python3.5/site-packages/telegram/ext/dispatcher.py", line 279, in process_update
    handler.handle_update(update, self)
  File "/home/p/.local/lib/python3.5/site-packages/telegram/ext/messagehandler.py", line 169, in handle_update
    return self.callback(dispatcher.bot, update, **optional_args)
  File "bot.py", line 25, in planet
    'Earth' : Earth,
NameError: name 'Earth' is not defined
telegram.ext.dispatcher - ERROR - An uncaught error was raised while processing the update
Traceback (most recent call last):
  File "/home/p/.local/lib/python3.5/site-packages/telegram/ext/dispatcher.py", line 279, in process_update
    handler.handle_update(update, self)
  File "/home/p/.local/lib/python3.5/site-packages/telegram/ext/messagehandler.py", line 169, in handle_update
    return self.callback(dispatcher.bot, update, **optional_args)
  File "bot.py", line 26, in planet
    location = constellation(m('2018/2/23'))
TypeError: 'NoneType' object is not callable
telegram.ext.dispatcher - ERROR - An uncaught error was raised while processing the update
Traceback (most recent call last):
  File "/home/p/.local/lib/python3.5/site-packages/telegram/ext/dispatcher.py", line 279, in process_update
    handler.handle_update(update, self)
  File "/home/p/.local/lib/python3.5/site-packages/telegram/ext/messagehandler.py", line 169, in handle_update
    return self.callback(dispatcher.bot, update, **optional_args)
  File "bot.py", line 26, in planet
    location = constellation(m('2018/2/23'))
TypeError: 'NoneType' object is not callable
telegram.ext.dispatcher - ERROR - An uncaught error was raised while processing the update
Traceback (most recent call last):
  File "/home/p/.local/lib/python3.5/site-packages/telegram/ext/dispatcher.py", line 279, in process_update
    handler.handle_update(update, self)
  File "/home/p/.local/lib/python3.5/site-packages/telegram/ext/messagehandler.py", line 169, in handle_update
    return self.callback(dispatcher.bot, update, **optional_args)
  File "bot.py", line 26, in planet
    location = constellation(m('2018/2/23'))
TypeError: 'NoneType' object is not callable
telegram.ext.dispatcher - ERROR - An uncaught error was raised while processing the update
Traceback (most recent call last):
  File "/home/p/.local/lib/python3.5/site-packages/telegram/ext/dispatcher.py", line 279, in process_update
    handler.handle_update(update, self)
  File "/home/p/.local/lib/python3.5/site-packages/telegram/ext/messagehandler.py", line 169, in handle_update
    return self.callback(dispatcher.bot, update, **optional_args)
  File "bot.py", line 26, in planet
    location = constellation(m('2018/2/23'))
TypeError: 'NoneType' object is not callable
telegram.ext.dispatcher - ERROR - An uncaught error was raised while processing the update
Traceback (most recent call last):
  File "/home/p/.local/lib/python3.5/site-packages/telegram/ext/dispatcher.py", line 279, in process_update
    handler.handle_update(update, self)
  File "/home/p/.local/lib/python3.5/site-packages/telegram/ext/messagehandler.py", line 169, in handle_update
    return self.callback(dispatcher.bot, update, **optional_args)
  File "bot.py", line 26, in planet
    'Earth' : Earth,
NameError: name 'Earth' is not defined
telegram.ext.dispatcher - ERROR - An uncaught error was raised while processing the update
Traceback (most recent call last):
  File "/home/p/.local/lib/python3.5/site-packages/telegram/ext/dispatcher.py", line 279, in process_update
    handler.handle_update(update, self)
  File "/home/p/.local/lib/python3.5/site-packages/telegram/ext/messagehandler.py", line 169, in handle_update
    return self.callback(dispatcher.bot, update, **optional_args)
  File "bot.py", line 26, in planet
    'Earth' : Earth,
NameError: name 'Earth' is not defined
telegram.ext.dispatcher - ERROR - An uncaught error was raised while processing the update
Traceback (most recent call last):
  File "/home/p/.local/lib/python3.5/site-packages/telegram/ext/dispatcher.py", line 279, in process_update
    handler.handle_update(update, self)
  File "/home/p/.local/lib/python3.5/site-packages/telegram/ext/messagehandler.py", line 169, in handle_update
    return self.callback(dispatcher.bot, update, **optional_args)
  File "bot.py", line 26, in planet
    'Earth' : Earth,
NameError: name 'Earth' is not defined
telegram.ext.dispatcher - ERROR - An uncaught error was raised while processing the update
Traceback (most recent call last):
  File "/home/p/.local/lib/python3.5/site-packages/telegram/ext/dispatcher.py", line 279, in process_update
    handler.handle_update(update, self)
  File "/home/p/.local/lib/python3.5/site-packages/telegram/ext/messagehandler.py", line 169, in handle_update
    return self.callback(dispatcher.bot, update, **optional_args)
  File "bot.py", line 26, in planet
    'Earth' : Earth
NameError: name 'Earth' is not defined
telegram.ext.dispatcher - ERROR - An uncaught error was raised while processing the update
Traceback (most recent call last):
  File "/home/p/.local/lib/python3.5/site-packages/telegram/ext/dispatcher.py", line 279, in process_update
    handler.handle_update(update, self)
  File "/home/p/.local/lib/python3.5/site-packages/telegram/ext/messagehandler.py", line 169, in handle_update
    return self.callback(dispatcher.bot, update, **optional_args)
  File "bot.py", line 26, in planet
    'Earth': Earth,
NameError: name 'Earth' is not defined
telegram.ext.dispatcher - ERROR - An uncaught error was raised while processing the update
Traceback (most recent call last):
  File "/home/p/.local/lib/python3.5/site-packages/telegram/ext/dispatcher.py", line 279, in process_update
    handler.handle_update(update, self)
  File "/home/p/.local/lib/python3.5/site-packages/telegram/ext/messagehandler.py", line 169, in handle_update
    return self.callback(dispatcher.bot, update, **optional_args)
  File "bot.py", line 36, in planet
    location = constellation(m('2018/2/23'))
TypeError: 'NoneType' object is not callable
telegram.ext.dispatcher - ERROR - An uncaught error was raised while processing the update
Traceback (most recent call last):
  File "/home/p/.local/lib/python3.5/site-packages/telegram/ext/dispatcher.py", line 279, in process_update
    handler.handle_update(update, self)
  File "/home/p/.local/lib/python3.5/site-packages/telegram/ext/messagehandler.py", line 169, in handle_update
    return self.callback(dispatcher.bot, update, **optional_args)
  File "bot.py", line 36, in planet
    location = constellation(m('2018/2/23'))
TypeError: 'NoneType' object is not callable
telegram.ext.dispatcher - ERROR - An uncaught error was raised while processing the update
Traceback (most recent call last):
  File "/home/p/.local/lib/python3.5/site-packages/telegram/ext/dispatcher.py", line 279, in process_update
    handler.handle_update(update, self)
  File "/home/p/.local/lib/python3.5/site-packages/telegram/ext/messagehandler.py", line 169, in handle_update
    return self.callback(dispatcher.bot, update, **optional_args)
  File "bot.py", line 36, in planet
    location = constellation(m('2018/2/23'))
TypeError: 'NoneType' object is not callable
telegram.ext.dispatcher - ERROR - An uncaught error was raised while processing the update
Traceback (most recent call last):
  File "/home/p/.local/lib/python3.5/site-packages/telegram/ext/dispatcher.py", line 279, in process_update
    handler.handle_update(update, self)
  File "/home/p/.local/lib/python3.5/site-packages/telegram/ext/messagehandler.py", line 169, in handle_update
    return self.callback(dispatcher.bot, update, **optional_args)
  File "bot.py", line 36, in planet
    location = constellation(m('2018/2/23'))
TypeError: 'NoneType' object is not callable
telegram.ext.dispatcher - ERROR - An uncaught error was raised while processing the update
Traceback (most recent call last):
  File "/home/p/.local/lib/python3.5/site-packages/telegram/ext/dispatcher.py", line 279, in process_update
    handler.handle_update(update, self)
  File "/home/p/.local/lib/python3.5/site-packages/telegram/ext/messagehandler.py", line 169, in handle_update
    return self.callback(dispatcher.bot, update, **optional_args)
  File "bot.py", line 36, in planet
    location = constellation(m('2018/2/23'))
TypeError: 'NoneType' object is not callable
telegram.ext.dispatcher - ERROR - An uncaught error was raised while processing the update
Traceback (most recent call last):
  File "/home/p/.local/lib/python3.5/site-packages/telegram/ext/dispatcher.py", line 279, in process_update
    handler.handle_update(update, self)
  File "/home/p/.local/lib/python3.5/site-packages/telegram/ext/messagehandler.py", line 169, in handle_update
    return self.callback(dispatcher.bot, update, **optional_args)
  File "bot.py", line 36, in planet
    location = constellation(m('2018/2/23'))
TypeError: 'NoneType' object is not callable
telegram.ext.dispatcher - ERROR - An uncaught error was raised while processing the update
Traceback (most recent call last):
  File "/home/p/.local/lib/python3.5/site-packages/telegram/ext/dispatcher.py", line 279, in process_update
    handler.handle_update(update, self)
  File "/home/p/.local/lib/python3.5/site-packages/telegram/ext/messagehandler.py", line 169, in handle_update
    return self.callback(dispatcher.bot, update, **optional_args)
  File "bot.py", line 36, in planet
    location = constellation(m('2018/2/23'))
TypeError: 'NoneType' object is not callable
telegram.ext.dispatcher - ERROR - An uncaught error was raised while processing the update
Traceback (most recent call last):
  File "/home/p/.local/lib/python3.5/site-packages/telegram/ext/dispatcher.py", line 279, in process_update
    handler.handle_update(update, self)
  File "/home/p/.local/lib/python3.5/site-packages/telegram/ext/messagehandler.py", line 169, in handle_update
    return self.callback(dispatcher.bot, update, **optional_args)
  File "bot.py", line 36, in planet
    location = constellation(m('2018/2/23'))
TypeError: 'NoneType' object is not callable
telegram.ext.dispatcher - ERROR - An uncaught error was raised while processing the update
Traceback (most recent call last):
  File "/home/p/.local/lib/python3.5/site-packages/telegram/ext/dispatcher.py", line 279, in process_update
    handler.handle_update(update, self)
  File "/home/p/.local/lib/python3.5/site-packages/telegram/ext/messagehandler.py", line 169, in handle_update
    return self.callback(dispatcher.bot, update, **optional_args)
  File "bot.py", line 36, in planet
    location = constellation(m('2018/2/23'))
TypeError: 'NoneType' object is not callable
telegram.ext.dispatcher - ERROR - An uncaught error was raised while processing the update
Traceback (most recent call last):
  File "/home/p/.local/lib/python3.5/site-packages/telegram/ext/dispatcher.py", line 279, in process_update
    handler.handle_update(update, self)
  File "/home/p/.local/lib/python3.5/site-packages/telegram/ext/messagehandler.py", line 169, in handle_update
    return self.callback(dispatcher.bot, update, **optional_args)
  File "bot.py", line 36, in planet
    location = constellation(m('2018/2/23'))
TypeError: 'NoneType' object is not callable
telegram.ext.dispatcher - ERROR - An uncaught error was raised while processing the update
Traceback (most recent call last):
  File "/home/p/.local/lib/python3.5/site-packages/telegram/ext/dispatcher.py", line 279, in process_update
    handler.handle_update(update, self)
  File "/home/p/.local/lib/python3.5/site-packages/telegram/ext/messagehandler.py", line 169, in handle_update
    return self.callback(dispatcher.bot, update, **optional_args)
  File "bot.py", line 36, in planet
    location = constellation(m('2018/2/23'))
TypeError: 'NoneType' object is not callable
telegram.ext.dispatcher - ERROR - An uncaught error was raised while processing the update
Traceback (most recent call last):
  File "/home/p/.local/lib/python3.5/site-packages/telegram/ext/dispatcher.py", line 279, in process_update
    handler.handle_update(update, self)
  File "/home/p/.local/lib/python3.5/site-packages/telegram/ext/messagehandler.py", line 169, in handle_update
    return self.callback(dispatcher.bot, update, **optional_args)
  File "bot.py", line 36, in planet
    location = constellation(m('2018/2/23'))
TypeError: 'NoneType' object is not callable
telegram.ext.dispatcher - ERROR - An uncaught error was raised while processing the update
Traceback (most recent call last):
  File "/home/p/.local/lib/python3.5/site-packages/telegram/ext/dispatcher.py", line 279, in process_update
    handler.handle_update(update, self)
  File "/home/p/.local/lib/python3.5/site-packages/telegram/ext/messagehandler.py", line 169, in handle_update
    return self.callback(dispatcher.bot, update, **optional_args)
  File "bot.py", line 36, in planet
    location = constellation(m('2018/2/23'))
TypeError: 'NoneType' object is not callable
telegram.ext.dispatcher - ERROR - An uncaught error was raised while processing the update
Traceback (most recent call last):
  File "/home/p/.local/lib/python3.5/site-packages/telegram/ext/dispatcher.py", line 279, in process_update
    handler.handle_update(update, self)
  File "/home/p/.local/lib/python3.5/site-packages/telegram/ext/messagehandler.py", line 169, in handle_update
    return self.callback(dispatcher.bot, update, **optional_args)
  File "bot.py", line 36, in planet
    location = constellation(m('2018/2/23'))
TypeError: 'NoneType' object is not callable
telegram.ext.dispatcher - ERROR - An uncaught error was raised while processing the update
Traceback (most recent call last):
  File "/home/p/.local/lib/python3.5/site-packages/telegram/ext/dispatcher.py", line 279, in process_update
    handler.handle_update(update, self)
  File "/home/p/.local/lib/python3.5/site-packages/telegram/ext/messagehandler.py", line 169, in handle_update
    return self.callback(dispatcher.bot, update, **optional_args)
  File "bot.py", line 36, in planet
    location = constellation(m('2018/2/23'))
TypeError: 'NoneType' object is not callable
telegram.ext.dispatcher - ERROR - An uncaught error was raised while processing the update
Traceback (most recent call last):
  File "/home/p/.local/lib/python3.5/site-packages/telegram/ext/dispatcher.py", line 279, in process_update
    handler.handle_update(update, self)
  File "/home/p/.local/lib/python3.5/site-packages/telegram/ext/messagehandler.py", line 169, in handle_update
    return self.callback(dispatcher.bot, update, **optional_args)
  File "bot.py", line 36, in planet
    location = constellation(m('2018/2/23'))
TypeError: 'NoneType' object is not callable
telegram.ext.dispatcher - ERROR - An uncaught error was raised while processing the update
Traceback (most recent call last):
  File "/home/p/.local/lib/python3.5/site-packages/telegram/ext/dispatcher.py", line 279, in process_update
    handler.handle_update(update, self)
  File "/home/p/.local/lib/python3.5/site-packages/telegram/ext/messagehandler.py", line 169, in handle_update
    return self.callback(dispatcher.bot, update, **optional_args)
  File "bot.py", line 36, in planet
    location = constellation(m('2018/2/23'))
TypeError: 'NoneType' object is not callable
telegram.ext.dispatcher - ERROR - An uncaught error was raised while processing the update
Traceback (most recent call last):
  File "/home/p/.local/lib/python3.5/site-packages/telegram/ext/dispatcher.py", line 279, in process_update
    handler.handle_update(update, self)
  File "/home/p/.local/lib/python3.5/site-packages/telegram/ext/messagehandler.py", line 169, in handle_update
    return self.callback(dispatcher.bot, update, **optional_args)
  File "bot.py", line 36, in planet
    location = constellation(m('2018/2/23'))
TypeError: 'NoneType' object is not callable
telegram.ext.dispatcher - ERROR - An uncaught error was raised while processing the update
Traceback (most recent call last):
  File "/home/p/.local/lib/python3.5/site-packages/telegram/ext/dispatcher.py", line 279, in process_update
    handler.handle_update(update, self)
  File "/home/p/.local/lib/python3.5/site-packages/telegram/ext/messagehandler.py", line 169, in handle_update
    return self.callback(dispatcher.bot, update, **optional_args)
  File "bot.py", line 36, in planet
    location = constellation(m('2018/2/23'))
TypeError: 'NoneType' object is not callable
telegram.ext.dispatcher - ERROR - An uncaught error was raised while processing the update
Traceback (most recent call last):
  File "/home/p/.local/lib/python3.5/site-packages/telegram/ext/dispatcher.py", line 279, in process_update
    handler.handle_update(update, self)
  File "/home/p/.local/lib/python3.5/site-packages/telegram/ext/messagehandler.py", line 169, in handle_update
    return self.callback(dispatcher.bot, update, **optional_args)
  File "bot.py", line 36, in planet
    location = constellation(m('2018/2/23'))
TypeError: 'NoneType' object is not callable
telegram.ext.dispatcher - ERROR - An uncaught error was raised while processing the update
Traceback (most recent call last):
  File "/home/p/.local/lib/python3.5/site-packages/telegram/ext/dispatcher.py", line 279, in process_update
    handler.handle_update(update, self)
  File "/home/p/.local/lib/python3.5/site-packages/telegram/ext/messagehandler.py", line 169, in handle_update
    return self.callback(dispatcher.bot, update, **optional_args)
  File "bot.py", line 36, in planet
    location = constellation(m('2018/2/23'))
TypeError: 'NoneType' object is not callable
telegram.ext.dispatcher - ERROR - An uncaught error was raised while processing the update
Traceback (most recent call last):
  File "/home/p/.local/lib/python3.5/site-packages/telegram/ext/dispatcher.py", line 279, in process_update
    handler.handle_update(update, self)
  File "/home/p/.local/lib/python3.5/site-packages/telegram/ext/messagehandler.py", line 169, in handle_update
    return self.callback(dispatcher.bot, update, **optional_args)
  File "bot.py", line 36, in planet
    location = constellation(m('2018/2/23'))
TypeError: 'NoneType' object is not callable
